Workbook

Sheet SSS1 ATTENDANCE 
E1: TIMSATH MODERN SCHOOL
E2: NURSERY, PRIMARY, AND COLLEDE
E3: 29, SALAMI STREET, BOGIJE, IBEJU LEKKI, LAGOS.
E4: TEL. 08162280395, 08165051119
C5: First____________Term 20__25 Class SSS1 Department____________________
B6: D. A | C6: NO. | D6: NAME (In Mixed school,Girls in red ink) | E6: Number in Admission Register | F6: Age | G6: Date of Promotion to this class | I6: 1 Week ending……19TH SEPTEMBER ...... M T W TH F | S6: 2 Week ending….....26TH SEPTEMBER .... M T W TH F | AC6: 3 Week ending……3RD OCTOBER ...... M T W TH F | AM6: 4 Week ending….10TH OCTOBER......... M T W TH F | AW6: 5 Week ending……17TH OCTOBER....... M T W TH F | BG6: 6 Week ending24TH.. OCTOBER M T W TH F | BQ6: 7 Week ending…..31ST OCTOBER M T W TH F | CA6: 8 Week ending…7TH NOVEMBER M T W TH F | CK6: 9 Week ending…..14TH NOVEMBER. M T W TH F | CU6: 10 Week ending…21ST NOVEMBER.......... M T W TH F | DE6: 11 Week ending….28TH NOVEMBER. M T W TH F | DO6: 12 Week ending 5TH DECEMBER M T W TH F | DY6: 13 Week ending….12TH DECEMBER.. M T W TH F | EI6: 14 Week ending…19TH DECEMBER. M T W TH F | ES6: WEEKLY 1 2 3 4 5 6 7 8 9 10 11 12 13 14 | FG6: NO. | FH6: Total Attendance for term | FI6: Brought forward | FJ6: Total
D7: FOR BOYS ONLY | I7: 1 | J7: 1 | K7: 1 | L7: 1 | M7: 1 | N7: 1 | O7: 1 | P7: 1 | Q7: 1 | R7: 1 | S7: 1 | T7: 1 | U7: 1 | V7: 1 | W7: 1 | X7: 1 | Y7: 1 | Z7: 1 | AA7: 1 | AB7: 1 | AC7: 1 | AD7: 1 | AE7: 1 | AF7: 1 | AI7: 1 | AJ7: 1 | AK7: 1 | AL7: 1 | AM7: 1 | AN7: 1 | AO7: 1 | AP7: 1 | AQ7: 1 | AR7: 1 | AS7: 1 | AT7: 1 | AU7: 1 | AV7: 1 | AW7: 1 | AX7: 1 | AY7: 1 | AZ7: 1 | BA7: 1 | BB7: 1 | BC7: 1 | BD7: 1 | BE7: 1 | BF7: 1 | BG7: 1 | BH7: 1 | BI7: 1 | BJ7: 1 | BK7: 1 | BL7: 1 | BM7: 1 | BN7: 1 | BO7: 1 | BP7: 1 | BQ7: 1 | BR7: 1 | BS7: 1 | BT7: 1 | BU7: 1 | BV7: 1 | BW7: 1 | BX7: 1 | BY7: 1 | BZ7: 1 | CK7: 1 | CL7: 1 | CM7: 1 | CN7: 1 | CO7: 1 | CP7: 1 | CQ7: 1 | CR7: 1 | CS7: 1 | CT7: 1 | CU7: 1 | CV7: 1 | CW7: 1 | CX7: 1 | CY7: 1 | CZ7: 1 | DA7: 1 | DB7: 1 | DC7: 1 | DD7: 1 | DE7: 1 | DF7: 1 | DG7: 1 | DH7: 1 | DI7: 1 | DJ7: 1 | DK7: 1 | DL7: 1 | DM7: 1 | DN7: 1 | DO7: 1 | DP7: 1 | DQ7: 1 | DR7: 1 | DS7: 1 | DT7: 1 | DU7: 1 | DV7: 1 | DW7: 1 | DX7: 1 | DY7: 1 | DZ7: 1 | EA7: 1 | EB7: 1 | EC7: 1 | ED7: 1 | EE7: 1 | EF7: 1 | EG7: 1 | EH7: 1 | EI7: 1 | EJ7: 1 | EK7: 1 | EL7: 1 | EM7: 1 | EN7: 1 | EO7: 1 | EP7: 1 | EQ7: 1 | ER7: 1
B8: =IF(ISTEXT(D8),1,0) -> 1 | C8: =ROW(D1) -> 1 | D8: ADEBANJI ANUOLWA | G8: 45915 | I8: 0 | J8: 0 | K8: 1 | L8: 1 | M8: 1 | N8: 1 | O8: 1 | P8: 1 | Q8: 1 | R8: 1 | S8: 1 | T8: 1 | U8: 1 | V8: 1 | W8: 1 | X8: 1 | Y8: 1 | Z8: 1 | AA8: 1 | AB8: 1 | AC8: 1 | AD8: 1 | AE8: 1 | AF8: 1 | AI8: 1 | AJ8: 1 | AK8: 1 | AL8: 1 | AM8: 1 | AN8: 1 | AO8: 1 | AP8: 1 | AQ8: 1 | AR8: 1 | AS8: 1 | AT8: 1 | AU8: 1 | AV8: 1 | AW8: 1 | AX8: 1 | AY8: 1 | AZ8: 1 | BA8: 1 | BB8: 1 | BC8: 1 | BD8: 1 | BE8: 1 | BF8: 1 | BG8: 1 | BH8: 1 | BI8: 1 | BJ8: 1 | BK8: 1 | BL8: 1 | BM8: 1 | BN8: 1 | BO8: 1 | BP8: 1 | BQ8: 1 | BR8: 1 | BS8: 1 | BT8: 1 | BU8: 1 | BV8: 1 | BW8: 1 | BX8: 1 | BY8: 1 | BZ8: 1 | CK8: 1 | CL8: 1 | CM8: 1 | CN8: 1 | CO8: 1 | CP8: 1 | CQ8: 1 | CR8: 1 | CS8: 1 | CT8: 1 | CU8: 1 | CV8: 1 | CW8: 1 | CX8: 1 | CY8: 1 | CZ8: 1 | DA8: 1 | DB8: 1 | DC8: 1 | DD8: 1 | DE8: 1 | DF8: 1 | DG8: 1 | DH8: 1 | DI8: 1 | DJ8: 1 | DK8: 1 | DL8: 1 | DM8: 1 | DN8: 1 | DO8: 1 | DP8: 1 | DQ8: 1 | DR8: 1 | DS8: 1 | DT8: 1 | DU8: 1 | DV8: 1 | DW8: 1 | DX8: 1 | DY8: 1 | DZ8: 1 | EA8: 1 | EB8: 1 | EC8: 1 | ED8: 1 | EE8: 1 | EF8: 1 | EG8: 1 | EH8: 1 | EI8: 1 | EJ8: 1 | EK8: 1 | EL8: 1 | EM8: 1 | EN8: 1 | EO8: 1 | EP8: 1 | EQ8: 1 | ER8: 1 | ES8: =SUM(I9:R9) -> 8 | ET8: =SUM(S8:AB8) -> 10 | EU8: =SUM(AC8:AL8) -> 8 | EV8: =SUM(AM8:AV8) -> 10 | EW8: =SUM(BG8:BP8) -> 10 | EX8: =SUM(BQ8:BZ8) -> 10 | EY8: =SUM(BQ8:BZ8) -> 10 | EZ8: =SUM(CA8:CJ8) -> 0 | FA8: =SUM(CK8:CT8) -> 10 | FB8: =SUM(CU8:DD8) -> 10 | FC8: =SUM(DE8:DN8) -> 10 | FD8: =SUM(DO8:DX8) -> 10 | FE8: =SUM(DY8:EH8) -> 10 | FF8: =SUM(EI8:ER8) -> 10 | FG8: 1 | FH8: =SUM(ES8:FF8) -> 126 | FI8: =SUM(I7:ER7)-SUM(ES8:FF8) -> 2 | FJ8: =SUM(FH8:FI8) -> 128
B9: =IF(ISTEXT(D9),1,0) -> 1 | C9: =ROW(D2) -> 2 | D9: AEJOH DANIEL | G9: 45915 | I9: 0 | J9: 0 | K9: 1 | L9: 1 | M9: 1 | N9: 1 | O9: 1 | P9: 1 | Q9: 1 | R9: 1 | S9: 1 | T9: 1 | U9: 1 | V9: 1 | W9: 1 | X9: 1 | Y9: 1 | Z9: 1 | AA9: 1 | AB9: 1 | AC9: 1 | AD9: 1 | AE9: 1 | AF9: 1 | AI9: 1 | AJ9: 1 | AK9: 1 | AL9: 1 | AM9: 1 | AN9: 1 | AO9: 1 | AP9: 1 | AQ9: 1 | AR9: 1 | AS9: 1 | AT9: 1 | AU9: 1 | AV9: 1 | AW9: 1 | AX9: 1 | AY9: 1 | AZ9: 1 | BA9: 1 | BB9: 1 | BC9: 1 | BD9: 1 | BE9: 1 | BF9: 1 | BG9: 1 | BH9: 1 | BI9: 1 | BJ9: 1 | BK9: 1 | BL9: 1 | BM9: 1 | BN9: 1 | BO9: 1 | BP9: 1 | BQ9: 1 | BR9: 1 | BS9: 1 | BT9: 1 | BU9: 1 | BV9: 1 | BW9: 1 | BX9: 1 | BY9: 1 | BZ9: 1 | CK9: 1 | CL9: 1 | CM9: 1 | CN9: 1 | CO9: 1 | CP9: 1 | CQ9: 1 | CR9: 1 | CS9: 1 | CT9: 1 | CU9: 1 | CV9: 1 | CW9: 1 | CX9: 1 | CY9: 1 | CZ9: 1 | DA9: 1 | DB9: 1 | DC9: 1 | DD9: 1 | DE9: 1 | DF9: 1 | DG9: 1 | DH9: 1 | DI9: 1 | DJ9: 1 | DK9: 1 | DL9: 1 | DM9: 1 | DN9: 1 | DO9: 1 | DP9: 1 | DQ9: 1 | DR9: 1 | DS9: 1 | DT9: 1 | DU9: 1 | DV9: 1 | DW9: 1 | DX9: 1 | DY9: 1 | DZ9: 1 | EA9: 1 | EB9: 1 | EC9: 1 | ED9: 1 | EE9: 1 | EF9: 1 | EG9: 1 | EH9: 1 | EI9: 1 | EJ9: 1 | EK9: 1 | EL9: 1 | EM9: 1 | EN9: 1 | EO9: 1 | EP9: 1 | EQ9: 1 | ER9: 1 | ES9: =SUM(I10:R10) -> 8 | ET9: =SUM(S9:AB9) -> 10 | EU9: =SUM(AC9:AL9) -> 8 | EV9: =SUM(AM9:AV9) -> 10 | EW9: =SUM(BG9:BP9) -> 10 | EX9: =SUM(BG9:BP9) -> 10 | EY9: =SUM(BQ9:BZ9) -> 10 | EZ9: =SUM(CA9:CJ9) -> 0 | FA9: =SUM(CK9:CT9) -> 10 | FB9: =SUM(CU9:DD9) -> 10 | FC9: =SUM(DE9:DN9) -> 10 | FD9: =SUM(DO9:DX9) -> 10 | FE9: =SUM(DY9:EH9) -> 10 | FF9: =SUM(EI9:ER9) -> 10 | FG9: 2 | FH9: =SUM(ES9:FF9) -> 126 | FI9: =SUM(I7:ER7)-SUM(ES9:FF9) -> 2 | FJ9: =SUM(FH9:FI9) -> 128
B10: =IF(ISTEXT(D10),1,0) -> 1 | C10: =ROW(D3) -> 3 | D10: ARIYIBI JAMIU | G10: 45915 | I10: 0 | J10: 0 | K10: 1 | L10: 1 | M10: 1 | N10: 1 | O10: 1 | P10: 1 | Q10: 1 | R10: 1 | S10: 1 | T10: 1 | U10: 1 | V10: 1 | W10: 1 | X10: 1 | Y10: 1 | Z10: 1 | AA10: 1 | AB10: 1 | AC10: 1 | AD10: 1 | AE10: 1 | AF10: 1 | AI10: 1 | AJ10: 1 | AK10: 1 | AL10: 1 | AM10: 1 | AN10: 1 | AO10: 1 | AP10: 1 | AQ10: 1 | AR10: 1 | AS10: 1 | AT10: 1 | AU10: 1 | AV10: 1 | AW10: 1 | AX10: 1 | AY10: 1 | AZ10: 1 | BA10: 1 | BB10: 1 | BC10: 1 | BD10: 1 | BE10: 1 | BF10: 1 | BG10: 1 | BH10: 1 | BI10: 1 | BJ10: 1 | BK10: 1 | BL10: 1 | BM10: 1 | BN10: 1 | BO10: 1 | BP10: 1 | BQ10: 1 | BR10: 1 | BS10: 1 | BT10: 1 | BU10: 1 | BV10: 1 | BW10: 1 | BX10: 1 | BY10: 1 | BZ10: 1 | CK10: 1 | CL10: 1 | CM10: 1 | CN10: 1 | CO10: 1 | CP10: 1 | CQ10: 1 | CR10: 1 | CS10: 1 | CT10: 1 | CU10: 1 | CV10: 1 | CW10: 1 | CX10: 1 | CY10: 1 | CZ10: 1 | DA10: 1 | DB10: 1 | DC10: 1 | DD10: 1 | DE10: 1 | DF10: 1 | DG10: 1 | DH10: 1 | DI10: 1 | DJ10: 1 | DK10: 1 | DL10: 1 | DM10: 1 | DN10: 1 | DO10: 1 | DP10: 1 | DQ10: 1 | DR10: 1 | DS10: 1 | DT10: 1 | DU10: 1 | DV10: 1 | DW10: 1 | DX10: 1 | DY10: 1 | DZ10: 1 | EA10: 1 | EB10: 1 | EC10: 1 | ED10: 1 | EE10: 1 | EF10: 1 | EG10: 1 | EH10: 1 | EI10: 1 | EJ10: 1 | EK10: 1 | EL10: 1 | EM10: 1 | EN10: 1 | EO10: 1 | EP10: 1 | EQ10: 1 | ER10: 1 | ES10: =SUM(I11:R11) -> 6 | ET10: =SUM(S10:AB10) -> 10 | EU10: =SUM(AC10:AL10) -> 8 | EV10: =SUM(AM10:AV10) -> 10 | EW10: =SUM(BG10:BP10) -> 10 | EX10: =SUM(BG10:BP10) -> 10 | EY10: =SUM(BQ10:BZ10) -> 10 | EZ10: =SUM(CA10:CJ10) -> 0 | FA10: =SUM(CK10:CT10) -> 10 | FB10: =SUM(CU10:DD10) -> 10 | FC10: =SUM(DE10:DN10) -> 10 | FD10: =SUM(DO10:DX10) -> 10 | FE10: =SUM(DY10:EH10) -> 10 | FF10: =SUM(EI10:ER10) -> 10 | FG10: 3 | FH10: =SUM(ES10:FF10) -> 124 | FI10: =SUM(I7:ER7)-SUM(ES10:FF10) -> 4 | FJ10: =SUM(FH10:FI10) -> 128
B11: =IF(ISTEXT(D11),1,0) -> 1 | C11: =ROW(D4) -> 4 | D11: AGUGBOM DESTINY | G11: 45915 | I11: 1 | J11: 1 | K11: 0 | L11: 0 | M11: 1 | N11: 1 | O11: 1 | P11: 1 | Q11: 0 | R11: 0 | S11: 1 | T11: 1 | U11: 1 | V11: 1 | W11: 0 | X11: 0 | Y11: 1 | Z11: 1 | AA11: 1 | AB11: 1 | AC11: 0 | AD11: 0 | AE11: 0 | AF11: 0 | AI11: 1 | AJ11: 1 | AK11: 1 | AL11: 1 | AM11: 1 | AN11: 1 | AO11: 0 | AP11: 0 | AQ11: 1 | AR11: 1 | AS11: 0 | AT11: 0 | AU11: 1 | AV11: 1 | AW11: 1 | AX11: 1 | AY11: 1 | AZ11: 1 | BA11: 1 | BB11: 1 | BC11: 1 | BD11: 1 | BE11: 1 | BF11: 1 | BG11: 1 | BH11: 1 | BI11: 1 | BJ11: 1 | BK11: 1 | BL11: 1 | BM11: 1 | BN11: 1 | BO11: 1 | BP11: 1 | BQ11: 1 | BR11: 1 | BS11: 1 | BT11: 1 | BU11: 1 | BV11: 1 | BW11: 1 | BX11: 1 | BY11: 1 | BZ11: 1 | CK11: 1 | CL11: 1 | CM11: 1 | CN11: 1 | CO11: 1 | CP11: 1 | CQ11: 1 | CR11: 1 | CS11: 1 | CT11: 1 | CU11: 1 | CV11: 1 | CW11: 1 | CX11: 1 | CY11: 1 | CZ11: 1 | DA11: 1 | DB11: 1 | DC11: 1 | DD11: 1 | DE11: 1 | DF11: 1 | DG11: 1 | DH11: 1 | DI11: 1 | DJ11: 1 | DK11: 1 | DL11: 1 | DM11: 1 | DN11: 1 | DO11: 1 | DP11: 1 | DQ11: 1 | DR11: 1 | DS11: 1 | DT11: 1 | DU11: 1 | DV11: 1 | DW11: 1 | DX11: 1 | DY11: 1 | DZ11: 1 | EA11: 1 | EB11: 1 | EC11: 1 | ED11: 1 | EE11: 1 | EF11: 1 | EG11: 1 | EH11: 1 | EI11: 1 | EJ11: 1 | EK11: 1 | EL11: 1 | EM11: 1 | EN11: 1 | EO11: 1 | EP11: 1 | EQ11: 1 | ER11: 1 | ES11: =SUM(I12:R12) -> 10 | ET11: =SUM(S11:AB11) -> 8 | EU11: =SUM(AC11:AL11) -> 4 | EV11: =SUM(AM11:AV11) -> 6 | EW11: =SUM(BG11:BP11) -> 10 | EX11: =SUM(BG11:BP11) -> 10 | EY11: =SUM(BQ11:BZ11) -> 10 | EZ11: =SUM(CA11:CJ11) -> 0 | FA11: =SUM(CK11:CT11) -> 10 | FB11: =SUM(CU11:DD11) -> 10 | FC11: =SUM(DE11:DN11) -> 10 | FD11: =SUM(DO11:DX11) -> 10 | FE11: =SUM(DY11:EH11) -> 10 | FF11: =SUM(EI11:ER11) -> 10 | FG11: =ROW(FG9) -> 9 | FH11: =SUM(ES11:FF11) -> 118 | FI11: =SUM(I7:ER7)-SUM(ES11:FF11) -> 10 | FJ11: =SUM(FH11:FI11) -> 128
B12: =IF(ISTEXT(D12),1,0) -> 1 | C12: =ROW(D5) -> 5 | D12: ALLI ABDULRASAQ | G12: 45915 | I12: 1 | J12: 1 | K12: 1 | L12: 1 | M12: 1 | N12: 1 | O12: 1 | P12: 1 | Q12: 1 | R12: 1 | S12: 1 | T12: 1 | U12: 1 | V12: 1 | W12: 1 | X12: 1 | Y12: 1 | Z12: 1 | AA12: 1 | AB12: 1 | AC12: 1 | AD12: 1 | AE12: 1 | AF12: 1 | AI12: 1 | AJ12: 1 | AK12: 1 | AL12: 1 | AM12: 1 | AN12: 1 | AO12: 1 | AP12: 1 | AQ12: 1 | AR12: 1 | AS12: 1 | AT12: 1 | AU12: 1 | AV12: 1 | AW12: 1 | AX12: 1 | AY12: 1 | AZ12: 1 | BA12: 1 | BB12: 1 | BC12: 1 | BD12: 1 | BE12: 1 | BF12: 1 | BG12: 1 | BH12: 1 | BI12: 1 | BJ12: 1 | BK12: 1 | BL12: 1 | BM12: 1 | BN12: 1 | BO12: 1 | BP12: 1 | BQ12: 1 | BR12: 1 | BS12: 1 | BT12: 1 | BU12: 1 | BV12: 1 | BW12: 1 | BX12: 1 | BY12: 1 | BZ12: 1 | CK12: 1 | CL12: 1 | CM12: 1 | CN12: 1 | CO12: 1 | CP12: 1 | CQ12: 1 | CR12: 1 | CS12: 1 | CT12: 1 | CU12: 1 | CV12: 1 | CW12: 1 | CX12: 1 | CY12: 1 | CZ12: 1 | DA12: 1 | DB12: 1 | DC12: 1 | DD12: 1 | DE12: 1 | DF12: 1 | DG12: 1 | DH12: 1 | DI12: 1 | DJ12: 1 | DK12: 1 | DL12: 1 | DM12: 1 | DN12: 1 | DO12: 1 | DP12: 1 | DQ12: 1 | DR12: 1 | DS12: 1 | DT12: 1 | DU12: 1 | DV12: 1 | DW12: 1 | DX12: 1 | DY12: 1 | DZ12: 1 | EA12: 1 | EB12: 1 | EC12: 1 | ED12: 1 | EE12: 1 | EF12: 1 | EG12: 1 | EH12: 1 | EI12: 1 | EJ12: 1 | EK12: 1 | EL12: 1 | EM12: 1 | EN12: 1 | EO12: 1 | EP12: 1 | EQ12: 1 | ER12: 1 | ES12: =SUM(I13:R13) -> 8 | ET12: =SUM(S12:AB12) -> 10 | EU12: =SUM(AC12:AL12) -> 8 | EV12: =SUM(AM12:AV12) -> 10 | EW12: =SUM(BG12:BP12) -> 10 | EX12: =SUM(BG12:BP12) -> 10 | EY12: =SUM(BQ12:BZ12) -> 10 | EZ12: =SUM(CA12:CJ12) -> 0 | FA12: =SUM(CK12:CT12) -> 10 | FB12: =SUM(CU12:DD12) -> 10 | FC12: =SUM(DE12:DN12) -> 10 | FD12: =SUM(DO12:DX12) -> 10 | FE12: =SUM(DY12:EH12) -> 10 | FF12: =SUM(EI12:ER12) -> 10 | FG12: =ROW(FG10) -> 10 | FH12: =SUM(ES12:FF12) -> 126 | FI12: =SUM(I7:ER7)-SUM(ES12:FF12) -> 2 | FJ12: =SUM(FH12:FI12) -> 128
B13: =IF(ISTEXT(D13),1,0) -> 1 | C13: =ROW(D6) -> 6 | D13: AZEEZ JOSHUA | G13: 45915 | I13: 0 | J13: 0 | K13: 1 | L13: 1 | M13: 1 | N13: 1 | O13: 1 | P13: 1 | Q13: 1 | R13: 1 | S13: 1 | T13: 1 | U13: 1 | V13: 1 | W13: 1 | X13: 1 | Y13: 1 | Z13: 1 | AA13: 1 | AB13: 1 | AC13: 1 | AD13: 1 | AE13: 1 | AF13: 1 | AI13: 1 | AJ13: 1 | AK13: 1 | AL13: 1 | AM13: 1 | AN13: 1 | AO13: 1 | AP13: 1 | AQ13: 1 | AR13: 1 | AS13: 1 | AT13: 1 | AU13: 1 | AV13: 1 | AW13: 1 | AX13: 1 | AY13: 1 | AZ13: 1 | BA13: 1 | BB13: 1 | BC13: 1 | BD13: 1 | BE13: 1 | BF13: 1 | BG13: 1 | BH13: 1 | BI13: 1 | BJ13: 1 | BK13: 1 | BL13: 1 | BM13: 1 | BN13: 1 | BO13: 1 | BP13: 1 | BQ13: 1 | BR13: 1 | BS13: 1 | BT13: 1 | BU13: 1 | BV13: 1 | BW13: 1 | BX13: 1 | BY13: 1 | BZ13: 1 | CK13: 1 | CL13: 1 | CM13: 1 | CN13: 1 | CO13: 1 | CP13: 1 | CQ13: 1 | CR13: 1 | CS13: 1 | CT13: 1 | CU13: 1 | CV13: 1 | CW13: 1 | CX13: 1 | CY13: 1 | CZ13: 1 | DA13: 1 | DB13: 1 | DC13: 1 | DD13: 1 | DE13: 1 | DF13: 1 | DG13: 1 | DH13: 1 | DI13: 1 | DJ13: 1 | DK13: 1 | DL13: 1 | DM13: 1 | DN13: 1 | DO13: 1 | DP13: 1 | DQ13: 1 | DR13: 1 | DS13: 1 | DT13: 1 | DU13: 1 | DV13: 1 | DW13: 1 | DX13: 1 | DY13: 1 | DZ13: 1 | EA13: 1 | EB13: 1 | EC13: 1 | ED13: 1 | EE13: 1 | EF13: 1 | EG13: 1 | EH13: 1 | EI13: 1 | EJ13: 1 | EK13: 1 | EL13: 1 | EM13: 1 | EN13: 1 | EO13: 1 | EP13: 1 | EQ13: 1 | ER13: 1 | ES13: =SUM(I14:R14) -> 8 | ET13: =SUM(S13:AB13) -> 10 | EU13: =SUM(AC13:AL13) -> 8 | EV13: =SUM(AM13:AV13) -> 10 | EW13: =SUM(BG13:BP13) -> 10 | EX13: =SUM(BG13:BP13) -> 10 | EY13: =SUM(BQ13:BZ13) -> 10 | EZ13: =SUM(CA13:CJ13) -> 0 | FA13: =SUM(CK13:CT13) -> 10 | FB13: =SUM(CU13:DD13) -> 10 | FC13: =SUM(DE13:DN13) -> 10 | FD13: =SUM(DO13:DX13) -> 10 | FE13: =SUM(DY13:EH13) -> 10 | FF13: =SUM(EI13:ER13) -> 10 | FG13: =ROW(FG11) -> 11 | FH13: =SUM(ES13:FF13) -> 126 | FI13: =SUM(I7:ER7)-SUM(ES13:FF13) -> 2 | FJ13: =SUM(FH13:FI13) -> 128
B14: =IF(ISTEXT(D14),1,0) -> 1 | C14: =ROW(D7) -> 7 | D14: BAKARE FARUQ | G14: 45915 | I14: 0 | J14: 0 | K14: 1 | L14: 1 | M14: 1 | N14: 1 | O14: 1 | P14: 1 | Q14: 1 | R14: 1 | S14: 1 | T14: 1 | U14: 1 | V14: 1 | W14: 1 | X14: 1 | Y14: 1 | Z14: 1 | AA14: 1 | AB14: 1 | AC14: 1 | AD14: 1 | AE14: 1 | AF14: 1 | AI14: 1 | AJ14: 1 | AK14: 1 | AL14: 1 | AM14: 1 | AN14: 1 | AO14: 1 | AP14: 1 | AQ14: 1 | AR14: 1 | AS14: 1 | AT14: 1 | AU14: 1 | AV14: 1 | AW14: 1 | AX14: 1 | AY14: 1 | AZ14: 1 | BA14: 1 | BB14: 1 | BC14: 1 | BD14: 1 | BE14: 1 | BF14: 1 | BG14: 1 | BH14: 1 | BI14: 1 | BJ14: 1 | BK14: 1 | BL14: 1 | BM14: 1 | BN14: 1 | BO14: 1 | BP14: 1 | BQ14: 1 | BR14: 1 | BS14: 1 | BT14: 1 | BU14: 1 | BV14: 1 | BW14: 1 | BX14: 1 | BY14: 1 | BZ14: 1 | CK14: 1 | CL14: 1 | CM14: 1 | CN14: 1 | CO14: 1 | CP14: 1 | CQ14: 1 | CR14: 1 | CS14: 1 | CT14: 1 | CU14: 1 | CV14: 1 | CW14: 1 | CX14: 1 | CY14: 1 | CZ14: 1 | DA14: 1 | DB14: 1 | DC14: 1 | DD14: 1 | DE14: 1 | DF14: 1 | DG14: 1 | DH14: 1 | DI14: 1 | DJ14: 1 | DK14: 1 | DL14: 1 | DM14: 1 | DN14: 1 | DO14: 1 | DP14: 1 | DQ14: 1 | DR14: 1 | DS14: 1 | DT14: 1 | DU14: 1 | DV14: 1 | DW14: 1 | DX14: 1 | DY14: 1 | DZ14: 1 | EA14: 1 | EB14: 1 | EC14: 1 | ED14: 1 | EE14: 1 | EF14: 1 | EG14: 1 | EH14: 1 | EI14: 1 | EJ14: 1 | EK14: 1 | EL14: 1 | EM14: 1 | EN14: 1 | EO14: 1 | EP14: 1 | EQ14: 1 | ER14: 1 | ES14: =SUM(I15:R15) -> 0 | ET14: =SUM(S14:AB14) -> 10 | EU14: =SUM(AC14:AL14) -> 8 | EV14: =SUM(AM14:AV14) -> 10 | EW14: =SUM(BG14:BP14) -> 10 | EX14: =SUM(BG14:BP14) -> 10 | EY14: =SUM(BQ14:BZ14) -> 10 | EZ14: =SUM(CA14:CJ14) -> 0 | FA14: =SUM(CK14:CT14) -> 10 | FB14: =SUM(CU14:DD14) -> 10 | FC14: =SUM(DE14:DN14) -> 10 | FD14: =SUM(DO14:DX14) -> 10 | FE14: =SUM(DY14:EH14) -> 10 | FF14: =SUM(EI14:ER14) -> 10 | FG14: =ROW(FG12) -> 12 | FH14: =SUM(ES14:FF14) -> 118 | FI14: =SUM(I7:ER7)-SUM(ES14:FF14) -> 10 | FJ14: =SUM(FH14:FI14) -> 128
B15: =IF(ISTEXT(D15),1,0) -> 1 | C15: =ROW(D8) -> 8 | D15: BELLO MUIZ | G15: 45915 | I15: 0 | J15: 0 | K15: 0 | L15: 0 | M15: 0 | N15: 0 | O15: 0 | P15: 0 | Q15: 0 | R15: 0 | S15: 1 | T15: 1 | U15: 1 | V15: 1 | W15: 1 | X15: 1 | Y15: 1 | Z15: 1 | AA15: 1 | AB15: 1 | AC15: 1 | AD15: 1 | AE15: 1 | AF15: 1 | AI15: 1 | AJ15: 1 | AK15: 1 | AL15: 1 | AM15: 1 | AN15: 1 | AO15: 1 | AP15: 1 | AQ15: 1 | AR15: 1 | AS15: 1 | AT15: 1 | AU15: 1 | AV15: 1 | AW15: 1 | AX15: 1 | AY15: 1 | AZ15: 1 | BA15: 1 | BB15: 1 | BC15: 1 | BD15: 1 | BE15: 1 | BF15: 1 | BG15: 1 | BH15: 1 | BI15: 1 | BJ15: 1 | BK15: 1 | BL15: 1 | BM15: 1 | BN15: 1 | BO15: 1 | BP15: 1 | BQ15: 1 | BR15: 1 | BS15: 1 | BT15: 1 | BU15: 1 | BV15: 1 | BW15: 1 | BX15: 1 | BY15: 1 | BZ15: 1 | CK15: 1 | CL15: 1 | CM15: 1 | CN15: 1 | CO15: 1 | CP15: 1 | CQ15: 1 | CR15: 1 | CS15: 1 | CT15: 1 | CU15: 1 | CV15: 1 | CW15: 1 | CX15: 1 | CY15: 1 | CZ15: 1 | DA15: 1 | DB15: 1 | DC15: 1 | DD15: 1 | DE15: 1 | DF15: 1 | DG15: 1 | DH15: 1 | DI15: 1 | DJ15: 1 | DK15: 1 | DL15: 1 | DM15: 1 | DN15: 1 | DO15: 1 | DP15: 1 | DQ15: 1 | DR15: 1 | DS15: 1 | DT15: 1 | DU15: 1 | DV15: 1 | DW15: 1 | DX15: 1 | DY15: 1 | DZ15: 1 | EA15: 1 | EB15: 1 | EC15: 1 | ED15: 1 | EE15: 1 | EF15: 1 | EG15: 1 | EH15: 1 | EI15: 1 | EJ15: 1 | EK15: 1 | EL15: 1 | EM15: 1 | EN15: 1 | EO15: 1 | EP15: 1 | EQ15: 1 | ER15: 1 | ES15: =SUM(I16:R16) -> 0 | ET15: =SUM(S15:AB15) -> 10 | EU15: =SUM(AC15:AL15) -> 8 | EV15: =SUM(AM15:AV15) -> 10 | EW15: =SUM(BG15:BP15) -> 10 | EX15: =SUM(BG15:BP15) -> 10 | EY15: =SUM(BQ15:BZ15) -> 10 | EZ15: =SUM(CA15:CJ15) -> 0 | FA15: =SUM(CK15:CT15) -> 10 | FB15: =SUM(CU15:DD15) -> 10 | FC15: =SUM(DE15:DN15) -> 10 | FD15: =SUM(DO15:DX15) -> 10 | FE15: =SUM(DY15:EH15) -> 10 | FF15: =SUM(EI15:ER15) -> 10 | FG15: =ROW(FG13) -> 13 | FH15: =SUM(ES15:FF15) -> 118 | FI15: =SUM(I7:ER7)-SUM(ES15:FF15) -> 10 | FJ15: =SUM(FH15:FI15) -> 128
B16: =IF(ISTEXT(D16),1,0) -> 1 | C16: =ROW(D9) -> 9 | D16: CHUKWU GABRIEL | G16: 45915 | I16: 0 | J16: 0 | K16: 0 | L16: 0 | M16: 0 | N16: 0 | O16: 0 | P16: 0 | Q16: 0 | R16: 0 | S16: 0 | T16: 0 | U16: 1 | V16: 1 | W16: 1 | X16: 1 | Y16: 1 | Z16: 1 | AA16: 1 | AB16: 1 | AC16: 1 | AD16: 1 | AE16: 1 | AF16: 1 | AI16: 1 | AJ16: 1 | AK16: 1 | AL16: 1 | AM16: 1 | AN16: 1 | AO16: 1 | AP16: 1 | AQ16: 1 | AR16: 1 | AS16: 1 | AT16: 1 | AU16: 1 | AV16: 1 | AW16: 1 | AX16: 1 | AY16: 1 | AZ16: 1 | BA16: 1 | BB16: 1 | BC16: 1 | BD16: 1 | BE16: 1 | BF16: 1 | BG16: 1 | BH16: 1 | BI16: 1 | BJ16: 1 | BK16: 1 | BL16: 1 | BM16: 1 | BN16: 1 | BO16: 1 | BP16: 1 | BQ16: 1 | BR16: 1 | BS16: 1 | BT16: 1 | BU16: 1 | BV16: 1 | BW16: 1 | BX16: 1 | BY16: 1 | BZ16: 1 | CK16: 1 | CL16: 1 | CM16: 1 | CN16: 1 | CO16: 1 | CP16: 1 | CQ16: 1 | CR16: 1 | CS16: 1 | CT16: 1 | CU16: 1 | CV16: 1 | CW16: 1 | CX16: 1 | CY16: 1 | CZ16: 1 | DA16: 1 | DB16: 1 | DC16: 1 | DD16: 1 | DE16: 1 | DF16: 1 | DG16: 1 | DH16: 1 | DI16: 1 | DJ16: 1 | DK16: 1 | DL16: 1 | DM16: 1 | DN16: 1 | DO16: 1 | DP16: 1 | DQ16: 1 | DR16: 1 | DS16: 1 | DT16: 1 | DU16: 1 | DV16: 1 | DW16: 1 | DX16: 1 | DY16: 1 | DZ16: 1 | EA16: 1 | EB16: 1 | EC16: 1 | ED16: 1 | EE16: 1 | EF16: 1 | EG16: 1 | EH16: 1 | EI16: 1 | EJ16: 1 | EK16: 1 | EL16: 1 | EM16: 1 | EN16: 1 | EO16: 1 | EP16: 1 | EQ16: 1 | ER16: 1 | ES16: =SUM(I17:R17) -> 10 | ET16: =SUM(S16:AB16) -> 8 | EU16: =SUM(AC16:AL16) -> 8 | EV16: =SUM(AM16:AV16) -> 10 | EW16: =SUM(BG16:BP16) -> 10 | EX16: =SUM(BG16:BP16) -> 10 | EY16: =SUM(BQ16:BZ16) -> 10 | EZ16: =SUM(CA16:CJ16) -> 0 | FA16: =SUM(CK16:CT16) -> 10 | FB16: =SUM(CU16:DD16) -> 10 | FC16: =SUM(DE16:DN16) -> 10 | FD16: =SUM(DO16:DX16) -> 10 | FE16: =SUM(DY16:EH16) -> 10 | FF16: =SUM(EI16:ER16) -> 10 | FG16: =ROW(FG14) -> 14 | FH16: =SUM(ES16:FF16) -> 126 | FI16: =SUM(I7:ER7)-SUM(ES16:FF16) -> 2 | FJ16: =SUM(FH16:FI16) -> 128
B17: =IF(ISTEXT(D17),1,0) -> 1 | C17: =ROW(D10) -> 10 | D17: EMMANUEL SEGUN | G17: 45915 | I17: 1 | J17: 1 | K17: 1 | L17: 1 | M17: 1 | N17: 1 | O17: 1 | P17: 1 | Q17: 1 | R17: 1 | S17: 1 | T17: 1 | U17: 1 | V17: 1 | W17: 1 | X17: 1 | Y17: 1 | Z17: 1 | AA17: 1 | AB17: 1 | AC17: 1 | AD17: 1 | AE17: 1 | AF17: 1 | AI17: 1 | AJ17: 1 | AK17: 1 | AL17: 1 | AM17: 1 | AN17: 1 | AO17: 1 | AP17: 1 | AQ17: 1 | AR17: 1 | AS17: 1 | AT17: 1 | AU17: 1 | AV17: 1 | AW17: 1 | AX17: 1 | AY17: 1 | AZ17: 1 | BA17: 1 | BB17: 1 | BC17: 1 | BD17: 1 | BE17: 1 | BF17: 1 | BG17: 1 | BH17: 1 | BI17: 1 | BJ17: 1 | BK17: 1 | BL17: 1 | BM17: 1 | BN17: 1 | BO17: 1 | BP17: 1 | BQ17: 1 | BR17: 1 | BS17: 1 | BT17: 1 | BU17: 1 | BV17: 1 | BW17: 1 | BX17: 1 | BY17: 1 | BZ17: 1 | CK17: 1 | CL17: 1 | CM17: 1 | CN17: 1 | CO17: 1 | CP17: 1 | CQ17: 1 | CR17: 1 | CS17: 1 | CT17: 1 | CU17: 1 | CV17: 1 | CW17: 1 | CX17: 1 | CY17: 1 | CZ17: 1 | DA17: 1 | DB17: 1 | DC17: 1 | DD17: 1 | DE17: 1 | DF17: 1 | DG17: 1 | DH17: 1 | DI17: 1 | DJ17: 1 | DK17: 1 | DL17: 1 | DM17: 1 | DN17: 1 | DO17: 1 | DP17: 1 | DQ17: 1 | DR17: 1 | DS17: 1 | DT17: 1 | DU17: 1 | DV17: 1 | DW17: 1 | DX17: 1 | DY17: 1 | DZ17: 1 | EA17: 1 | EB17: 1 | EC17: 1 | ED17: 1 | EE17: 1 | EF17: 1 | EG17: 1 | EH17: 1 | EI17: 1 | EJ17: 1 | EK17: 1 | EL17: 1 | EM17: 1 | EN17: 1 | EO17: 1 | EP17: 1 | EQ17: 1 | ER17: 1 | ES17: =SUM(I18:R18) -> 10 | ET17: =SUM(S17:AB17) -> 10 | EU17: =SUM(AC17:AL17) -> 8 | EV17: =SUM(AM17:AV17) -> 10 | EW17: =SUM(BG17:BP17) -> 10 | EX17: =SUM(BG17:BP17) -> 10 | EY17: =SUM(BQ17:BZ17) -> 10 | EZ17: =SUM(CA17:CJ17) -> 0 | FA17: =SUM(CK17:CT17) -> 10 | FB17: =SUM(CU17:DD17) -> 10 | FC17: =SUM(DE17:DN17) -> 10 | FD17: =SUM(DO17:DX17) -> 10 | FE17: =SUM(DY17:EH17) -> 10 | FF17: =SUM(EI17:ER17) -> 10 | FG17: =ROW(FG15) -> 15 | FH17: =SUM(ES17:FF17) -> 128 | FI17: =SUM(I7:ER7)-SUM(ES17:FF17) -> 0 | FJ17: =SUM(FH17:FI17) -> 128
B18: =IF(ISTEXT(D18),1,0) -> 1 | C18: =ROW(D11) -> 11 | D18: EZE MICHEAL | G18: 45915 | I18: 1 | J18: 1 | K18: 1 | L18: 1 | M18: 1 | N18: 1 | O18: 1 | P18: 1 | Q18: 1 | R18: 1 | S18: 1 | T18: 1 | U18: 1 | V18: 1 | W18: 1 | X18: 1 | Y18: 1 | Z18: 1 | AA18: 1 | AB18: 1 | AC18: 1 | AD18: 1 | AE18: 1 | AF18: 1 | AI18: 1 | AJ18: 1 | AK18: 1 | AL18: 1 | AM18: 1 | AN18: 1 | AO18: 1 | AP18: 1 | AQ18: 1 | AR18: 1 | AS18: 0 | AT18: 0 | AU18: 0 | AV18: 0 | AW18: 1 | AX18: 1 | AY18: 1 | AZ18: 1 | BA18: 1 | BB18: 1 | BC18: 1 | BD18: 1 | BE18: 1 | BF18: 1 | BG18: 1 | BH18: 1 | BI18: 1 | BJ18: 1 | BK18: 1 | BL18: 1 | BM18: 1 | BN18: 1 | BO18: 1 | BP18: 1 | BQ18: 1 | BR18: 1 | BS18: 1 | BT18: 1 | BU18: 1 | BV18: 1 | BW18: 1 | BX18: 1 | BY18: 1 | BZ18: 1 | CK18: 1 | CL18: 1 | CM18: 1 | CN18: 1 | CO18: 1 | CP18: 1 | CQ18: 1 | CR18: 1 | CS18: 1 | CT18: 1 | CU18: 1 | CV18: 1 | CW18: 1 | CX18: 1 | CY18: 1 | CZ18: 1 | DA18: 1 | DB18: 1 | DC18: 1 | DD18: 1 | DE18: 1 | DF18: 1 | DG18: 1 | DH18: 1 | DI18: 1 | DJ18: 1 | DK18: 1 | DL18: 1 | DM18: 1 | DN18: 1 | DO18: 1 | DP18: 1 | DQ18: 1 | DR18: 1 | DS18: 1 | DT18: 1 | DU18: 1 | DV18: 1 | DW18: 1 | DX18: 1 | DY18: 0 | DZ18: 0 | EA18: 1 | EB18: 1 | EC18: 0 | ED18: 0 | EE18: 1 | EF18: 1 | EG18: 1 | EH18: 1 | EI18: 0 | EJ18: 0 | EK18: 0 | EL18: 0 | EM18: 0 | EN18: 0 | EO18: 0 | EP18: 0 | EQ18: 0 | ER18: 0 | ES18: =SUM(I19:R19) -> 2 | ET18: =SUM(S18:AB18) -> 10 | EU18: =SUM(AC18:AL18) -> 8 | EV18: =SUM(AM18:AV18) -> 6 | EW18: =SUM(BG18:BP18) -> 10 | EX18: =SUM(BG18:BP18) -> 10 | EY18: =SUM(BQ18:BZ18) -> 10 | EZ18: =SUM(CA18:CJ18) -> 0 | FA18: =SUM(CK18:CT18) -> 10 | FB18: =SUM(CU18:DD18) -> 10 | FC18: =SUM(DE18:DN18) -> 10 | FD18: =SUM(DO18:DX18) -> 10 | FE18: =SUM(DY18:EH18) -> 6 | FF18: =SUM(EI18:ER18) -> 0 | FG18: =ROW(FG16) -> 16 | FH18: =SUM(ES18:FF18) -> 102 | FI18: =SUM(I7:ER7)-SUM(ES18:FF18) -> 26 | FJ18: =SUM(FH18:FI18) -> 128
B19: =IF(ISTEXT(D19),1,0) -> 1 | C19: =ROW(D12) -> 12 | D19: FOLORUNSHO OLORUNWA | G19: 45915 | I19: 0 | J19: 0 | K19: 0 | L19: 0 | M19: 1 | N19: 1 | O19: 0 | P19: 0 | Q19: 0 | R19: O | S19: 1 | T19: 1 | U19: 1 | V19: 1 | W19: 1 | X19: 1 | Y19: 1 | Z19: 1 | AA19: 1 | AB19: 1 | AC19: 1 | AD19: 1 | AE19: 1 | AF19: 1 | AI19: 1 | AJ19: 1 | AK19: 0 | AL19: 0 | AM19: 1 | AN19: 1 | AO19: 1 | AP19: 1 | AQ19: 1 | AR19: 1 | AS19: 1 | AT19: 1 | AU19: 0 | AV19: 0 | AW19: 0 | AX19: 0 | AY19: 1 | AZ19: 1 | BA19: 1 | BB19: 1 | BC19: 1 | BD19: 1 | BE19: 1 | BF19: 1 | BG19: 1 | BH19: 1 | BI19: 1 | BJ19: 1 | BK19: 1 | BL19: 1 | BM19: 1 | BN19: 1 | BO19: 1 | BP19: 1 | BQ19: 1 | BR19: 1 | BS19: 1 | BT19: 1 | BU19: 1 | BV19: 1 | BW19: 1 | BX19: 1 | BY19: 1 | BZ19: 1 | CK19: 1 | CL19: 1 | CM19: 1 | CN19: 1 | CO19: 1 | CP19: 1 | CQ19: 1 | CR19: 1 | CS19: 1 | CT19: 1 | CU19: 1 | CV19: 1 | CW19: 1 | CX19: 1 | CY19: 1 | CZ19: 1 | DA19: 1 | DB19: 1 | DC19: 1 | DD19: 1 | DE19: 1 | DF19: 1 | DG19: 1 | DH19: 1 | DI19: 1 | DJ19: 1 | DK19: 1 | DL19: 1 | DM19: 1 | DN19: 1 | DO19: 1 | DP19: 1 | DQ19: 1 | DR19: 1 | DS19: 1 | DT19: 1 | DU19: 1 | DV19: 1 | DW19: 1 | DX19: 1 | DY19: 1 | DZ19: 1 | EA19: 1 | EB19: 1 | EC19: 1 | ED19: 1 | EE19: 1 | EF19: 1 | EG19: 1 | EH19: 1 | EI19: 1 | EJ19: 1 | EK19: 1 | EL19: 1 | EM19: 1 | EN19: 1 | EO19: 1 | EP19: 1 | EQ19: 1 | ER19: 1 | ES19: =SUM(I20:R20) -> 10 | ET19: =SUM(S19:AB19) -> 10 | EU19: =SUM(AC19:AL19) -> 6 | EV19: =SUM(AM19:AV19) -> 8 | EW19: =SUM(BG19:BP19) -> 10 | EX19: =SUM(BG19:BP19) -> 10 | EY19: =SUM(BQ19:BZ19) -> 10 | EZ19: =SUM(CA19:CJ19) -> 0 | FA19: =SUM(CK19:CT19) -> 10 | FB19: =SUM(CU19:DD19) -> 10 | FC19: =SUM(DE19:DN19) -> 10 | FD19: =SUM(DO19:DX19) -> 10 | FE19: =SUM(DY19:EH19) -> 10 | FF19: =SUM(EI19:ER19) -> 10 | FG19: =ROW(FG17) -> 17 | FH19: =SUM(ES19:FF19) -> 124 | FI19: =SUM(I7:ER7)-SUM(ES19:FF19) -> 4 | FJ19: =SUM(FH19:FI19) -> 128
B20: =IF(ISTEXT(D20),1,0) -> 1 | C20: =ROW(D13) -> 13 | D20: HADI ALAMEEN | G20: 45915 | I20: 1 | J20: 1 | K20: 1 | L20: 1 | M20: 1 | N20: 1 | O20: 1 | P20: 1 | Q20: 1 | R20: 1 | S20: 1 | T20: 1 | U20: 1 | V20: 1 | W20: 1 | X20: 1 | Y20: 1 | Z20: 1 | AA20: 1 | AB20: 1 | AC20: 1 | AD20: 1 | AE20: 1 | AF20: 1 | AI20: 1 | AJ20: 1 | AK20: 1 | AL20: 1 | AM20: 1 | AN20: 1 | AO20: 1 | AP20: 1 | AQ20: 1 | AR20: 1 | AS20: 1 | AT20: 1 | AU20: 1 | AV20: 1 | AW20: 1 | AX20: 1 | AY20: 1 | AZ20: 1 | BA20: 1 | BB20: 1 | BC20: 0 | BD20: 0 | BE20: 1 | BF20: 1 | BG20: 1 | BH20: 1 | BI20: 1 | BJ20: 1 | BK20: 1 | BL20: 1 | BM20: 1 | BN20: 1 | BO20: 1 | BP20: 1 | BQ20: 1 | BR20: 1 | BS20: 1 | BT20: 1 | BU20: 1 | BV20: 1 | BW20: 1 | BX20: 1 | BY20: 1 | BZ20: 1 | CK20: 1 | CL20: 1 | CM20: 1 | CN20: 1 | CO20: 1 | CP20: 1 | CQ20: 1 | CR20: 1 | CS20: 1 | CT20: 1 | CU20: 1 | CV20: 1 | CW20: 1 | CX20: 1 | CY20: 1 | CZ20: 1 | DA20: 1 | DB20: 1 | DC20: 1 | DD20: 1 | DE20: 1 | DF20: 1 | DG20: 1 | DH20: 1 | DI20: 1 | DJ20: 1 | DK20: 1 | DL20: 1 | DM20: 1 | DN20: 1 | DO20: 1 | DP20: 1 | DQ20: 1 | DR20: 1 | DS20: 1 | DT20: 1 | DU20: 1 | DV20: 1 | DW20: 1 | DX20: 1 | DY20: 1 | DZ20: 1 | EA20: 1 | EB20: 1 | EC20: 1 | ED20: 1 | EE20: 1 | EF20: 1 | EG20: 1 | EH20: 1 | EI20: 1 | EJ20: 1 | EK20: 1 | EL20: 1 | EM20: 1 | EN20: 1 | EO20: 1 | EP20: 1 | EQ20: 1 | ER20: 1 | ES20: =SUM(I21:R21) -> 6 | ET20: =SUM(S20:AB20) -> 10 | EU20: =SUM(AC20:AL20) -> 8 | EV20: =SUM(AM20:AV20) -> 10 | EW20: =SUM(BG20:BP20) -> 10 | EX20: =SUM(BG20:BP20) -> 10 | EY20: =SUM(BQ20:BZ20) -> 10 | EZ20: =SUM(CA20:CJ20) -> 0 | FA20: =SUM(CK20:CT20) -> 10 | FB20: =SUM(CU20:DD20) -> 10 | FC20: =SUM(DE20:DN20) -> 10 | FD20: =SUM(DO20:DX20) -> 10 | FE20: =SUM(DY20:EH20) -> 10 | FF20: =SUM(EI20:ER20) -> 10 | FG20: =ROW(FG18) -> 18 | FH20: =SUM(ES20:FF20) -> 124 | FI20: =SUM(I7:ER7)-SUM(ES20:FF20) -> 4 | FJ20: =SUM(FH20:FI20) -> 128
B21: =IF(ISTEXT(D21),1,0) -> 1 | C21: =ROW(D14) -> 14 | D21: HONNOUN AYOMIDE | G21: 45915 | I21: 0 | J21: 0 | K21: 0 | L21: 0 | M21: 1 | N21: 1 | O21: 1 | P21: 1 | Q21: 1 | R21: 1 | S21: 1 | T21: 1 | U21: 1 | V21: 1 | W21: 1 | X21: 1 | Y21: 1 | Z21: 1 | AA21: 1 | AB21: 1 | AC21: 1 | AD21: 1 | AE21: 1 | AF21: 1 | AI21: 1 | AJ21: 1 | AK21: 1 | AL21: 1 | AM21: 1 | AN21: 1 | AO21: 1 | AP21: 1 | AQ21: 1 | AR21: 1 | AS21: 1 | AT21: 1 | AU21: 1 | AV21: 1 | AW21: 1 | AX21: 1 | AY21: 1 | AZ21: 1 | BA21: 1 | BB21: 1 | BC21: 1 | BD21: 1 | BE21: 1 | BF21: 1 | BG21: 1 | BH21: 1 | BI21: 1 | BJ21: 1 | BK21: 1 | BL21: 1 | BM21: 1 | BN21: 1 | BO21: 1 | BP21: 1 | BQ21: 1 | BR21: 1 | BS21: 1 | BT21: 1 | BU21: 1 | BV21: 1 | BW21: 1 | BX21: 1 | BY21: 1 | BZ21: 1 | CK21: 1 | CL21: 1 | CM21: 1 | CN21: 1 | CO21: 1 | CP21: 1 | CQ21: 1 | CR21: 1 | CS21: 1 | CT21: 1 | CU21: 1 | CV21: 1 | CW21: 1 | CX21: 1 | CY21: 1 | CZ21: 1 | DA21: 1 | DB21: 1 | DC21: 1 | DD21: 1 | DE21: 1 | DF21: 1 | DG21: 1 | DH21: 1 | DI21: 1 | DJ21: 1 | DK21: 1 | DL21: 1 | DM21: 1 | DN21: 1 | DO21: 1 | DP21: 1 | DQ21: 1 | DR21: 1 | DS21: 1 | DT21: 1 | DU21: 1 | DV21: 1 | DW21: 1 | DX21: 1 | DY21: 1 | DZ21: 1 | EA21: 1 | EB21: 1 | EC21: 1 | ED21: 1 | EE21: 1 | EF21: 1 | EG21: 1 | EH21: 1 | EI21: 1 | EJ21: 1 | EK21: 1 | EL21: 1 | EM21: 1 | EN21: 1 | EO21: 1 | EP21: 1 | EQ21: 1 | ER21: 1 | ES21: =SUM(I22:R22) -> 8 | ET21: 10 | EU21: =SUM(AC21:AL21) -> 8 | EV21: =SUM(AM21:AV21) -> 10 | EW21: =SUM(BG21:BP21) -> 10 | EX21: =SUM(BG21:BP21) -> 10 | EY21: =SUM(BQ21:BZ21) -> 10 | EZ21: =SUM(CA21:CJ21) -> 0 | FA21: =SUM(CK21:CT21) -> 10 | FB21: =SUM(CU21:DD21) -> 10 | FC21: =SUM(DE21:DN21) -> 10 | FD21: =SUM(DO21:DX21) -> 10 | FE21: =SUM(DY21:EH21) -> 10 | FF21: =SUM(EI21:ER21) -> 10 | FG21: =ROW(FG19) -> 19 | FH21: =SUM(ES21:FF21) -> 126 | FI21: =SUM(I7:ER7)-SUM(ES21:FF21) -> 2 | FJ21: =SUM(FH21:FI21) -> 128
B22: =IF(ISTEXT(D22),1,0) -> 1 | C22: =ROW(D15) -> 15 | D22: IYIOLA QUADRI | G22: 45915 | I22: 0 | J22: 0 | K22: 1 | L22: 1 | M22: 1 | N22: 1 | O22: 1 | P22: 1 | Q22: 1 | R22: 1 | S22: 1 | T22: 1 | U22: 1 | V22: 1 | W22: 1 | X22: 1 | Y22: 1 | Z22: 1 | AA22: 1 | AB22: 1 | AC22: 1 | AD22: 1 | AE22: 1 | AF22: 1 | AI22: 1 | AJ22: 1 | AK22: 1 | AL22: 1 | AM22: 1 | AN22: 1 | AO22: 1 | AP22: 1 | AQ22: 1 | AR22: 1 | AS22: 1 | AT22: 1 | AU22: 1 | AV22: 1 | AW22: 1 | AX22: 1 | AY22: 1 | AZ22: 1 | BA22: 1 | BB22: 1 | BC22: 1 | BD22: 1 | BE22: 1 | BF22: 1 | BG22: 1 | BH22: 1 | BI22: 1 | BJ22: 1 | BK22: 1 | BL22: 1 | BM22: 1 | BN22: 1 | BO22: 1 | BP22: 1 | BQ22: 1 | BR22: 1 | BS22: 1 | BT22: 1 | BU22: 1 | BV22: 1 | BW22: 1 | BX22: 1 | BY22: 1 | BZ22: 1 | CK22: 1 | CL22: 1 | CM22: 1 | CN22: 1 | CO22: 1 | CP22: 1 | CQ22: 1 | CR22: 1 | CS22: 1 | CT22: 1 | CU22: 1 | CV22: 1 | CW22: 1 | CX22: 1 | CY22: 1 | CZ22: 1 | DA22: 1 | DB22: 1 | DC22: 1 | DD22: 1 | DE22: 1 | DF22: 1 | DG22: 1 | DH22: 1 | DI22: 1 | DJ22: 1 | DK22: 1 | DL22: 1 | DM22: 1 | DN22: 1 | DO22: 1 | DP22: 1 | DQ22: 1 | DR22: 1 | DS22: 1 | DT22: 1 | DU22: 1 | DV22: 1 | DW22: 1 | DX22: 1 | DY22: 1 | DZ22: 1 | EA22: 1 | EB22: 1 | EC22: 1 | ED22: 1 | EE22: 1 | EF22: 1 | EG22: 1 | EH22: 1 | EI22: 1 | EJ22: 1 | EK22: 1 | EL22: 1 | EM22: 1 | EN22: 1 | EO22: 1 | EP22: 1 | EQ22: 1 | ER22: 1 | ES22: =SUM(I23:R23) -> 0 | ET22: =SUM(S22:AB22) -> 10 | EU22: =SUM(AC22:AL22) -> 8 | EV22: =SUM(AM22:AV22) -> 10 | EW22: =SUM(BG22:BP22) -> 10 | EX22: =SUM(BG22:BP22) -> 10 | EY22: =SUM(BQ22:BZ22) -> 10 | EZ22: =SUM(CA22:CJ22) -> 0 | FA22: =SUM(CK22:CT22) -> 10 | FB22: =SUM(CU22:DD22) -> 10 | FC22: =SUM(DE22:DN22) -> 10 | FD22: =SUM(DO22:DX22) -> 10 | FE22: =SUM(DY22:EH22) -> 10 | FF22: =SUM(EI22:ER22) -> 10 | FG22: =ROW(FG20) -> 20 | FH22: =SUM(ES22:FF22) -> 118 | FI22: =SUM(I7:ER7)-SUM(ES22:FF22) -> 10 | FJ22: =SUM(FH22:FI22) -> 128
B23: =IF(ISTEXT(D23),1,0) -> 1 | C23: =ROW(D16) -> 16 | D23: JEGEDI SAMUEL | G23: 45915 | I23: 0 | J23: 0 | K23: 0 | L23: 0 | M23: 0 | N23: 0 | O23: 0 | P23: 0 | Q23: 0 | R23: 0 | S23: 1 | T23: 1 | U23: 1 | V23: 1 | W23: 1 | X23: 1 | Y23: 1 | Z23: 1 | AA23: 1 | AB23: 1 | AC23: 1 | AD23: 1 | AE23: 1 | AF23: 1 | AI23: 1 | AJ23: 1 | AK23: 1 | AL23: 1 | AM23: 1 | AN23: 1 | AO23: 0 | AP23: 0 | AQ23: 1 | AR23: 1 | AS23: 1 | AT23: 1 | AU23: 0 | AV23: 0 | AW23: 0 | AX23: 0 | AY23: 0 | AZ23: 0 | BA23: 1 | BB23: 1 | BC23: 1 | BD23: 1 | BE23: 1 | BF23: 1 | BG23: 1 | BH23: 1 | BI23: 1 | BJ23: 1 | BK23: 1 | BL23: 1 | BM23: 1 | BN23: 1 | BO23: 1 | BP23: 1 | BQ23: 1 | BR23: 1 | BS23: 1 | BT23: 1 | BU23: 1 | BV23: 1 | BW23: 1 | BX23: 1 | BY23: 1 | BZ23: 1 | CK23: 1 | CL23: 1 | CM23: 1 | CN23: 1 | CO23: 1 | CP23: 1 | CQ23: 1 | CR23: 1 | CS23: 1 | CT23: 1 | CU23: 1 | CV23: 1 | CW23: 1 | CX23: 1 | CY23: 1 | CZ23: 1 | DA23: 1 | DB23: 1 | DC23: 1 | DD23: 1 | DE23: 1 | DF23: 1 | DG23: 1 | DH23: 1 | DI23: 0 | DJ23: 0 | DK23: 0 | DL23: 0 | DM23: 0 | DN23: 0 | DO23: 1 | DP23: 1 | DQ23: 0 | DR23: 0 | DS23: 0 | DT23: 0 | DU23: 1 | DV23: 1 | DW23: 1 | DX23: 1 | DY23: 1 | DZ23: 1 | EA23: 1 | EB23: 1 | EC23: 1 | ED23: 1 | EE23: 1 | EF23: 1 | EG23: 1 | EH23: 1 | EI23: 1 | EJ23: 1 | EK23: 1 | EL23: 1 | EM23: 1 | EN23: 1 | EO23: 1 | EP23: 1 | EQ23: 1 | ER23: 1 | ES23: =SUM(I24:R24) -> 6 | ET23: =SUM(S23:AB23) -> 10 | EU23: =SUM(AC23:AL23) -> 8 | EV23: =SUM(AM23:AV23) -> 6 | EW23: =SUM(BG23:BP23) -> 10 | EX23: =SUM(BG23:BP23) -> 10 | EY23: =SUM(BQ23:BZ23) -> 10 | EZ23: =SUM(CA23:CJ23) -> 0 | FA23: =SUM(CK23:CT23) -> 10 | FB23: =SUM(CU23:DD23) -> 10 | FC23: =SUM(DE23:DN23) -> 4 | FD23: =SUM(DO23:DX23) -> 6 | FE23: =SUM(DY23:EH23) -> 10 | FF23: =SUM(EI23:ER23) -> 10 | FG23: =ROW(FG21) -> 21 | FH23: =SUM(ES23:FF23) -> 110 | FI23: =SUM(I7:ER7)-SUM(ES23:FF23) -> 18 | FJ23: =SUM(FH23:FI23) -> 128
B24: =IF(ISTEXT(D24),1,0) -> 1 | C24: =ROW(D17) -> 17 | D24: NOSIRUDEEN MALIK | G24: 45915 | I24: 0 | J24: 0 | K24: 0 | L24: 0 | M24: 1 | N24: 1 | O24: 1 | P24: 1 | Q24: 1 | R24: 1 | S24: 1 | T24: 1 | U24: 1 | V24: 1 | W24: 1 | X24: 1 | Y24: 1 | Z24: 1 | AA24: 1 | AB24: 1 | AC24: 1 | AD24: 1 | AE24: 1 | AF24: 1 | AI24: 1 | AJ24: 1 | AK24: 1 | AL24: 1 | AM24: 1 | AN24: 1 | AO24: 1 | AP24: 1 | AQ24: 1 | AR24: 1 | AS24: 1 | AT24: 1 | AU24: 1 | AV24: 1 | AW24: 1 | AX24: 1 | AY24: 1 | AZ24: 1 | BA24: 1 | BB24: 1 | BC24: 1 | BD24: 1 | BE24: 1 | BF24: 1 | BG24: 1 | BH24: 1 | BI24: 1 | BJ24: 1 | BK24: 1 | BL24: 1 | BM24: 1 | BN24: 1 | BO24: 1 | BP24: 1 | BQ24: 1 | BR24: 1 | BS24: 1 | BT24: 1 | BU24: 1 | BV24: 1 | BW24: 1 | BX24: 1 | BY24: 1 | BZ24: 1 | CK24: 1 | CL24: 1 | CM24: 1 | CN24: 1 | CO24: 1 | CP24: 1 | CQ24: 1 | CR24: 1 | CS24: 1 | CT24: 1 | CU24: 0 | CV24: 0 | CW24: 0 | CX24: 0 | CY24: 0 | CZ24: 0 | DA24: 1 | DB24: 1 | DC24: 1 | DD24: 1 | DE24: 1 | DF24: 1 | DG24: 1 | DH24: 1 | DI24: 1 | DJ24: 1 | DK24: 1 | DL24: 1 | DM24: 1 | DN24: 1 | DO24: 1 | DP24: 1 | DQ24: 1 | DR24: 1 | DS24: 1 | DT24: 1 | DU24: 1 | DV24: 1 | DW24: 1 | DX24: 1 | DY24: 1 | DZ24: 1 | EA24: 1 | EB24: 1 | EC24: 1 | ED24: 1 | EE24: 1 | EF24: 1 | EG24: 1 | EH24: 1 | EI24: 1 | EJ24: 1 | EK24: 1 | EL24: 1 | EM24: 1 | EN24: 1 | EO24: 1 | EP24: 1 | EQ24: 1 | ER24: 1 | ES24: =SUM(I25:R25) -> 8 | ET24: =SUM(S24:AB24) -> 10 | EU24: =SUM(AC24:AL24) -> 8 | EV24: =SUM(AM24:AV24) -> 10 | EW24: =SUM(BG24:BP24) -> 10 | EX24: =SUM(BG24:BP24) -> 10 | EY24: =SUM(BQ24:BZ24) -> 10 | EZ24: =SUM(CA24:CJ24) -> 0 | FA24: =SUM(CK24:CT24) -> 10 | FB24: =SUM(CU24:DD24) -> 4 | FC24: =SUM(DE24:DN24) -> 10 | FD24: =SUM(DO24:DX24) -> 10 | FE24: =SUM(DY24:EH24) -> 10 | FF24: =SUM(EI24:ER24) -> 10 | FG24: =ROW(FG22) -> 22 | FH24: =SUM(ES24:FF24) -> 120 | FI24: =SUM(I7:ER7)-SUM(ES24:FF24) -> 8 | FJ24: =SUM(FH24:FI24) -> 128
B25: =IF(ISTEXT(D25),1,0) -> 1 | C25: 18 | D25: NOSIRUDEEN USMAN | G25: 45915 | I25: 0 | J25: 0 | K25: 1 | L25: 1 | M25: 1 | N25: 1 | O25: 1 | P25: 1 | Q25: 1 | R25: 1 | S25: 1 | T25: 1 | U25: 0 | V25: 0 | W25: 1 | X25: 1 | Y25: 1 | Z25: 1 | AA25: 1 | AB25: 1 | AC25: 1 | AD25: 1 | AE25: 1 | AF25: 1 | AI25: 1 | AJ25: 1 | AK25: 1 | AL25: 1 | AM25: 1 | AN25: 1 | AO25: 1 | AP25: 1 | AQ25: 1 | AR25: 1 | AS25: 1 | AT25: 1 | AU25: 1 | AV25: 1 | AW25: 1 | AX25: 1 | AY25: 1 | AZ25: 1 | BA25: 1 | BB25: 1 | BC25: 1 | BD25: 1 | BE25: 1 | BF25: 1 | BG25: 1 | BH25: 1 | BI25: 1 | BJ25: 1 | BK25: 1 | BL25: 1 | BM25: 1 | BN25: 1 | BO25: 1 | BP25: 1 | BQ25: 1 | BR25: 1 | BS25: 1 | BT25: 1 | BU25: 1 | BV25: 1 | BW25: 1 | BX25: 1 | BY25: 1 | BZ25: 1 | CK25: 1 | CL25: 1 | CM25: 1 | CN25: 1 | CO25: 1 | CP25: 1 | CQ25: 1 | CR25: 1 | CS25: 1 | CT25: 1 | CU25: 0 | CV25: 0 | CW25: 0 | CX25: 0 | CY25: 0 | CZ25: 0 | DA25: 1 | DB25: 1 | DC25: 1 | DD25: 1 | DE25: 1 | DF25: 1 | DG25: 1 | DH25: 1 | DI25: 1 | DJ25: 1 | DK25: 1 | DL25: 1 | DM25: 1 | DN25: 1 | DO25: 1 | DP25: 1 | DQ25: 1 | DR25: 1 | DS25: 1 | DT25: 1 | DU25: 1 | DV25: 1 | DW25: 1 | DX25: 1 | DY25: 1 | DZ25: 1 | EA25: 1 | EB25: 1 | EC25: 1 | ED25: 1 | EE25: 1 | EF25: 1 | EG25: 1 | EH25: 1 | EI25: 1 | EJ25: 1 | EK25: 1 | EL25: 1 | EM25: 1 | EN25: 1 | EO25: 1 | EP25: 1 | EQ25: 1 | ER25: 1 | ES25: =SUM(I26:R26) -> 0 | ET25: =SUM(S25:AB25) -> 8 | EU25: =SUM(AC25:AL25) -> 8 | EV25: =SUM(AM25:AV25) -> 10 | EW25: =SUM(BG25:BP25) -> 10 | EX25: =SUM(BG25:BP25) -> 10 | EY25: =SUM(BQ25:BZ25) -> 10 | EZ25: =SUM(CA25:CJ25) -> 0 | FA25: =SUM(CK25:CT25) -> 10 | FB25: =SUM(CU25:DD25) -> 4 | FC25: =SUM(DE25:DN25) -> 10 | FD25: =SUM(DO25:DX25) -> 10 | FE25: =SUM(DY25:EH25) -> 10 | FF25: =SUM(EI25:ER25) -> 10 | FG25: =ROW(FG23) -> 23 | FH25: =SUM(ES25:FF25) -> 110 | FI25: =SUM(I7:ER7)-SUM(ES25:FF25) -> 18 | FJ25: =SUM(FH25:FI25) -> 128
B26: =IF(ISTEXT(D26),1,0) -> 1 | C26: 19 | D26: OKORIE DOMINION | G26: 45915 | I26: 0 | J26: 0 | K26: 0 | L26: 0 | M26: 0 | N26: 0 | O26: 0 | P26: 0 | Q26: 0 | R26: 0 | S26: 0 | T26: 0 | U26: 0 | V26: 0 | W26: 1 | X26: 1 | Y26: 1 | Z26: 1 | AA26: 1 | AB26: 1 | AC26: 1 | AD26: 1 | AE26: 1 | AF26: 1 | AI26: 0 | AJ26: 0 | AK26: 0 | AL26: 0 | AM26: 0 | AN26: 0 | AO26: 0 | AP26: 0 | AQ26: 0 | AR26: 0 | AS26: 0 | AT26: 0 | AU26: 1 | AV26: 1 | AW26: 0 | AX26: 0 | AY26: 0 | AZ26: 0 | BA26: 0 | BB26: 0 | BC26: 0 | BD26: 0 | BE26: 0 | BF26: 0 | BG26: 0 | BH26: 0 | BI26: 0 | BJ26: 0 | BK26: 0 | BL26: 0 | BM26: 0 | BN26: 0 | BO26: 0 | BP26: 0 | BQ26: 0 | BR26: 0 | BS26: 0 | BT26: 0 | BU26: 0 | BV26: 0 | BW26: 0 | BX26: 0 | BY26: 0 | BZ26: 0 | CK26: 0 | CL26: 0 | CM26: 0 | CN26: 0 | CO26: 0 | CP26: 0 | CQ26: 0 | CR26: 0 | CS26: 0 | CT26: 0 | CU26: 0 | CV26: 0 | CW26: 0 | CX26: 0 | CY26: 0 | CZ26: 0 | DA26: 0 | DB26: 0 | DC26: 0 | DD26: 0 | DE26: 0 | DF26: 0 | DG26: 0 | DH26: 0 | DI26: 0 | DJ26: 0 | DK26: 0 | DL26: 0 | DM26: 0 | DN26: 0 | DO26: 0 | DP26: 0 | DQ26: 0 | DR26: 0 | DS26: 0 | DT26: 0 | DU26: 0 | DV26: 0 | DW26: 0 | DX26: 0 | DY26: 0 | DZ26: 0 | EA26: 0 | EB26: 0 | EC26: 0 | ED26: 0 | EE26: 0 | EF26: 0 | EG26: 0 | EH26: 0 | EI26: 0 | EJ26: 0 | EK26: 0 | EL26: 0 | EM26: 0 | EN26: 0 | EO26: 0 | EP26: 0 | EQ26: 0 | ER26: 0 | ES26: =SUM(I27:R27) -> 10 | ET26: =SUM(S26:AB26) -> 6 | EU26: =SUM(AC26:AL26) -> 4 | EV26: =SUM(AM26:AV26) -> 2 | EW26: =SUM(BG26:BP26) -> 0 | EX26: =SUM(BG26:BP26) -> 0 | EY26: =SUM(BQ26:BZ26) -> 0 | EZ26: =SUM(CA26:CJ26) -> 0 | FA26: =SUM(CK26:CT26) -> 0 | FB26: =SUM(CU26:DD26) -> 0 | FC26: =SUM(DE26:DN26) -> 0 | FD26: =SUM(DO26:DX26) -> 0 | FE26: =SUM(DY26:EH26) -> 0 | FF26: =SUM(EI26:ER26) -> 0 | FG26: =ROW(FG24) -> 24 | FH26: =SUM(ES26:FF26) -> 22 | FI26: =SUM(I7:ER7)-SUM(ES26:FF26) -> 106 | FJ26: =SUM(FH26:FI26) -> 128
B27: =IF(ISTEXT(D27),1,0) -> 1 | C27: 20 | D27: ONI ISREAL | G27: 45915 | I27: 1 | J27: 1 | K27: 1 | L27: 1 | M27: 1 | N27: 1 | O27: 1 | P27: 1 | Q27: 1 | R27: 1 | S27: 1 | T27: 1 | U27: 1 | V27: 1 | W27: 1 | X27: 1 | Y27: 1 | Z27: 1 | AA27: 1 | AB27: 1 | AC27: 1 | AD27: 1 | AE27: 1 | AF27: 1 | AI27: 1 | AJ27: 1 | AK27: 1 | AL27: 1 | AM27: 1 | AN27: 1 | AO27: 1 | AP27: 1 | AQ27: 1 | AR27: 1 | AS27: 1 | AT27: 1 | AU27: 1 | AV27: 1 | AW27: 1 | AX27: 1 | AY27: 1 | AZ27: 1 | BA27: 1 | BB27: 1 | BC27: 1 | BD27: 1 | BE27: 1 | BF27: 1 | BG27: 1 | BH27: 1 | BI27: 1 | BJ27: 1 | BK27: 1 | BL27: 1 | BM27: 1 | BN27: 1 | BO27: 0 | BP27: 0 | BQ27: 0 | BR27: 0 | BS27: 0 | BT27: 0 | BU27: 0 | BV27: 0 | BW27: 0 | BX27: 0 | BY27: 0 | BZ27: 0 | CK27: 1 | CL27: 1 | CM27: 1 | CN27: 1 | CO27: 1 | CP27: 1 | CQ27: 1 | CR27: 1 | CS27: 1 | CT27: 1 | CU27: 1 | CV27: 1 | CW27: 1 | CX27: 1 | CY27: 1 | CZ27: 1 | DA27: 1 | DB27: 1 | DC27: 1 | DD27: 1 | DE27: 1 | DF27: 1 | DG27: 1 | DH27: 1 | DI27: 1 | DJ27: 1 | DK27: 1 | DL27: 1 | DM27: 1 | DN27: 1 | DO27: 1 | DP27: 1 | DQ27: 1 | DR27: 1 | DS27: 1 | DT27: 1 | DU27: 1 | DV27: 1 | DW27: 1 | DX27: 1 | DY27: 1 | DZ27: 1 | EA27: 1 | EB27: 1 | EC27: 1 | ED27: 1 | EE27: 1 | EF27: 1 | EG27: 1 | EH27: 1 | EI27: 1 | EJ27: 1 | EK27: 1 | EL27: 1 | EM27: 1 | EN27: 1 | EO27: 1 | EP27: 1 | EQ27: 1 | ER27: 1 | ES27: =SUM(I28:R28) -> 10 | ET27: =SUM(S27:AB27) -> 10 | EU27: =SUM(AC27:AL27) -> 8 | EV27: =SUM(AM27:AV27) -> 10 | EW27: =SUM(BG27:BP27) -> 8 | EX27: =SUM(BG27:BP27) -> 8 | EY27: =SUM(BQ27:BZ27) -> 0 | EZ27: =SUM(CA27:CJ27) -> 0 | FA27: =SUM(CK27:CT27) -> 10 | FB27: =SUM(CU27:DD27) -> 10 | FC27: =SUM(DE27:DN27) -> 10 | FD27: =SUM(DO27:DX27) -> 10 | FE27: =SUM(DY27:EH27) -> 10 | FF27: =SUM(EI27:ER27) -> 10 | FG27: =ROW(FG25) -> 25 | FH27: =SUM(ES27:FF27) -> 114 | FI27: =SUM(I7:ER7)-SUM(ES27:FF27) -> 14 | FJ27: =SUM(FH27:FI27) -> 128
B28: =IF(ISTEXT(D28),1,0) -> 1 | C28: 21 | D28: OLAIYA FERANMI | G28: 45915 | I28: 1 | J28: 1 | K28: 1 | L28: 1 | M28: 1 | N28: 1 | O28: 1 | P28: 1 | Q28: 1 | R28: 1 | S28: 1 | T28: 1 | U28: 1 | V28: 1 | W28: 1 | X28: 1 | Y28: 1 | Z28: 1 | AA28: 1 | AB28: 1 | AC28: 1 | AD28: 1 | AE28: 1 | AF28: 1 | AI28: 0 | AJ28: 0 | AK28: 1 | AL28: 1 | AM28: 1 | AN28: 1 | AO28: 1 | AP28: 1 | AQ28: 1 | AR28: 1 | AS28: 1 | AT28: 1 | AU28: 1 | AV28: 1 | AW28: 1 | AX28: 1 | AY28: 1 | AZ28: 1 | BA28: 1 | BB28: 1 | BC28: 1 | BD28: 1 | BE28: 1 | BF28: 1 | BG28: 1 | BH28: 1 | BI28: 1 | BJ28: 1 | BK28: 1 | BL28: 1 | BM28: 1 | BN28: 1 | BO28: 1 | BP28: 1 | BQ28: 1 | BR28: 1 | BS28: 1 | BT28: 1 | BU28: 1 | BV28: 1 | BW28: 1 | BX28: 1 | BY28: 1 | BZ28: 1 | CK28: 1 | CL28: 1 | CM28: 1 | CN28: 1 | CO28: 1 | CP28: 1 | CQ28: 1 | CR28: 1 | CS28: 1 | CT28: 1 | CU28: 1 | CV28: 1 | CW28: 1 | CX28: 1 | CY28: 1 | CZ28: 1 | DA28: 1 | DB28: 1 | DC28: 1 | DD28: 1 | DE28: 1 | DF28: 1 | DG28: 1 | DH28: 1 | DI28: 1 | DJ28: 1 | DK28: 1 | DL28: 1 | DM28: 1 | DN28: 1 | DO28: 1 | DP28: 1 | DQ28: 1 | DR28: 1 | DS28: 1 | DT28: 1 | DU28: 1 | DV28: 1 | DW28: 1 | DX28: 1 | DY28: 1 | DZ28: 1 | EA28: 1 | EB28: 1 | EC28: 1 | ED28: 1 | EE28: 1 | EF28: 1 | EG28: 1 | EH28: 1 | EI28: 1 | EJ28: 1 | EK28: 1 | EL28: 1 | EM28: 1 | EN28: 1 | EO28: 1 | EP28: 1 | EQ28: 1 | ER28: 1 | ES28: =SUM(I29:R29) -> 10 | ET28: =SUM(S28:AB28) -> 10 | EU28: =SUM(AC28:AL28) -> 6 | EV28: =SUM(AM28:AV28) -> 10 | EW28: =SUM(BG28:BP28) -> 10 | EX28: =SUM(BG28:BP28) -> 10 | EY28: =SUM(BQ28:BZ28) -> 10 | EZ28: =SUM(CA28:CJ28) -> 0 | FA28: =SUM(CK28:CT28) -> 10 | FB28: =SUM(CU28:DD28) -> 10 | FC28: =SUM(DE28:DN28) -> 10 | FD28: =SUM(DO28:DX28) -> 10 | FE28: =SUM(DY28:EH28) -> 10 | FF28: =SUM(EI28:ER28) -> 10 | FG28: =ROW(FG26) -> 26 | FH28: =SUM(ES28:FF28) -> 126 | FI28: =SUM(I7:ER7)-SUM(ES28:FF28) -> 2 | FJ28: =SUM(FH28:FI28) -> 128
B29: =IF(ISTEXT(D29),1,0) -> 1 | C29: 22 | D29: OYEWOLE JOHN | G29: 45915 | I29: 1 | J29: 1 | K29: 1 | L29: 1 | M29: 1 | N29: 1 | O29: 1 | P29: 1 | Q29: 1 | R29: 1 | S29: 1 | T29: 1 | U29: 1 | V29: 1 | W29: 1 | X29: 1 | Y29: 1 | Z29: 1 | AA29: 1 | AB29: 1 | AC29: 1 | AD29: 1 | AE29: 1 | AF29: 1 | AI29: 1 | AJ29: 1 | AK29: 1 | AL29: 1 | AM29: 1 | AN29: 1 | AO29: 1 | AP29: 1 | AQ29: 1 | AR29: 1 | AS29: 1 | AT29: 1 | AU29: 1 | AV29: 1 | AW29: 1 | AX29: 1 | AY29: 1 | AZ29: 1 | BA29: 1 | BB29: 1 | BC29: 1 | BD29: 1 | BE29: 1 | BF29: 1 | BG29: 1 | BH29: 1 | BI29: 1 | BJ29: 1 | BK29: 1 | BL29: 1 | BM29: 1 | BN29: 1 | BO29: 1 | BP29: 1 | BQ29: 1 | BR29: 1 | BS29: 1 | BT29: 1 | BU29: 1 | BV29: 1 | BW29: 1 | BX29: 1 | BY29: 1 | BZ29: 1 | CK29: 1 | CL29: 1 | CM29: 1 | CN29: 1 | CO29: 1 | CP29: 1 | CQ29: 1 | CR29: 1 | CS29: 1 | CT29: 1 | CU29: 1 | CV29: 1 | CW29: 1 | CX29: 1 | CY29: 1 | CZ29: 1 | DA29: 1 | DB29: 1 | DC29: 1 | DD29: 1 | DE29: 1 | DF29: 1 | DG29: 1 | DH29: 1 | DI29: 1 | DJ29: 1 | DK29: 1 | DL29: 1 | DM29: 1 | DN29: 1 | DO29: 1 | DP29: 1 | DQ29: 1 | DR29: 1 | DS29: 1 | DT29: 1 | DU29: 1 | DV29: 1 | DW29: 1 | DX29: 1 | DY29: 1 | DZ29: 1 | EA29: 1 | EB29: 1 | EC29: 1 | ED29: 1 | EE29: 1 | EF29: 1 | EG29: 1 | EH29: 1 | EI29: 1 | EJ29: 1 | EK29: 1 | EL29: 1 | EM29: 1 | EN29: 1 | EO29: 1 | EP29: 1 | EQ29: 1 | ER29: 1 | ES29: =SUM(I30:R30) -> 0 | ET29: =SUM(S29:AB29) -> 10 | EU29: =SUM(AC29:AL29) -> 8 | EV29: =SUM(AM29:AV29) -> 10 | EW29: =SUM(BG29:BP29) -> 10 | EX29: =SUM(BG29:BP29) -> 10 | EY29: =SUM(BQ29:BZ29) -> 10 | EZ29: =SUM(CA29:CJ29) -> 0 | FA29: =SUM(CK29:CT29) -> 10 | FB29: =SUM(CU29:DD29) -> 10 | FC29: =SUM(DE29:DN29) -> 10 | FD29: =SUM(DO29:DX29) -> 10 | FE29: =SUM(DY29:EH29) -> 10 | FF29: =SUM(EI29:ER29) -> 10 | FG29: =ROW(FG27) -> 27 | FH29: =SUM(ES29:FF29) -> 118 | FI29: =SUM(I7:ER7)-SUM(ES29:FF29) -> 10 | FJ29: =SUM(FH29:FI29) -> 128
B30: =IF(ISTEXT(D30),1,0) -> 1 | C30: 23 | D30: SHITTU BASIT | G30: 45915 | I30: 0 | J30: 0 | K30: 0 | L30: 0 | M30: 0 | N30: 0 | O30: 0 | P30: 0 | Q30: 0 | R30: 0 | S30: 1 | T30: 1 | U30: 1 | V30: 1 | W30: 1 | X30: 1 | Y30: 1 | Z30: 1 | AA30: 1 | AB30: 1 | AC30: 1 | AD30: 1 | AE30: 1 | AF30: 1 | AI30: 1 | AJ30: 1 | AK30: 1 | AL30: 1 | AM30: 1 | AN30: 1 | AO30: 1 | AP30: 1 | AQ30: 1 | AR30: 1 | AS30: 1 | AT30: 1 | AU30: 1 | AV30: 1 | AW30: 1 | AX30: 1 | AY30: 1 | AZ30: 1 | BA30: 1 | BB30: 1 | BC30: 1 | BD30: 1 | BE30: 1 | BF30: 1 | BG30: 1 | BH30: 1 | BI30: 1 | BJ30: 1 | BK30: 1 | BL30: 1 | BM30: 1 | BN30: 1 | BO30: 1 | BP30: 1 | BQ30: 1 | BR30: 1 | BS30: 1 | BT30: 1 | BU30: 1 | BV30: 1 | BW30: 1 | BX30: 1 | BY30: 1 | BZ30: 1 | CK30: 1 | CL30: 1 | CM30: 1 | CN30: 1 | CO30: 1 | CP30: 1 | CQ30: 1 | CR30: 1 | CS30: 1 | CT30: 1 | CU30: 1 | CV30: 1 | CW30: 1 | CX30: 1 | CY30: 1 | CZ30: 1 | DA30: 1 | DB30: 1 | DC30: 1 | DD30: 1 | DE30: 1 | DF30: 1 | DG30: 1 | DH30: 1 | DI30: 1 | DJ30: 1 | DK30: 1 | DL30: 1 | DM30: 1 | DN30: 1 | DO30: 1 | DP30: 1 | DQ30: 1 | DR30: 1 | DS30: 1 | DT30: 1 | DU30: 1 | DV30: 1 | DW30: 1 | DX30: 1 | DY30: 1 | DZ30: 1 | EA30: 1 | EB30: 1 | EC30: 1 | ED30: 1 | EE30: 1 | EF30: 1 | EG30: 1 | EH30: 1 | EI30: 1 | EJ30: 1 | EK30: 1 | EL30: 1 | EM30: 1 | EN30: 1 | EO30: 1 | EP30: 1 | EQ30: 1 | ER30: 1 | ES30: =SUM(I31:R31) -> 0 | ET30: =SUM(S30:AB30) -> 10 | EU30: =SUM(AC30:AL30) -> 8 | EV30: =SUM(AM30:AV30) -> 10 | EW30: =SUM(BG30:BP30) -> 10 | EX30: =SUM(BG30:BP30) -> 10 | EY30: =SUM(BQ30:BZ30) -> 10 | EZ30: =SUM(CA30:CJ30) -> 0 | FA30: =SUM(CK30:CT30) -> 10 | FB30: =SUM(CU30:DD30) -> 10 | FC30: =SUM(DE30:DN30) -> 10 | FD30: =SUM(DO30:DX30) -> 10 | FE30: =SUM(DY30:EH30) -> 10 | FF30: =SUM(EI30:ER30) -> 10 | FG30: =ROW(FG28) -> 28 | FH30: =SUM(ES30:FF30) -> 118 | FI30: =SUM(I7:ER7)-SUM(ES30:FF30) -> 10 | FJ30: =SUM(FH30:FI30) -> 128
B31: =IF(ISTEXT(D31),1,0) -> 1 | C31: 24 | D31: WILLAMS ABLODUN | G31: 45915 | I31: 0 | J31: 0 | K31: 0 | L31: 0 | M31: 0 | N31: 0 | O31: 0 | P31: 0 | Q31: 0 | R31: 0 | S31: 1 | T31: 1 | U31: 1 | V31: 1 | W31: 1 | X31: 1 | Y31: 1 | Z31: 1 | AA31: 1 | AB31: 1 | AC31: 1 | AD31: 1 | AE31: 1 | AF31: 1 | AI31: 0 | AJ31: 0 | AK31: 1 | AL31: 1 | AM31: 1 | AN31: 1 | AO31: 1 | AP31: 1 | AQ31: 1 | AR31: 1 | AS31: 1 | AT31: 1 | AU31: 1 | AV31: 1 | AW31: 1 | AX31: 1 | AY31: 1 | AZ31: 1 | BA31: 1 | BB31: 1 | BC31: 1 | BD31: 1 | BE31: 1 | BF31: 1 | BG31: 1 | BH31: 1 | BI31: 1 | BJ31: 1 | BK31: 1 | BL31: 1 | BM31: 1 | BN31: 1 | BO31: 1 | BP31: 1 | BQ31: 1 | BR31: 1 | BS31: 1 | BT31: 1 | BU31: 1 | BV31: 1 | BW31: 1 | BX31: 1 | BY31: 1 | BZ31: 1 | CK31: 1 | CL31: 1 | CM31: 1 | CN31: 1 | CO31: 1 | CP31: 1 | CQ31: 1 | CR31: 1 | CS31: 1 | CT31: 1 | CU31: 1 | CV31: 1 | CW31: 1 | CX31: 1 | CY31: 1 | CZ31: 1 | DA31: 1 | DB31: 1 | DC31: 1 | DD31: 1 | DE31: 1 | DF31: 1 | DG31: 1 | DH31: 1 | DI31: 1 | DJ31: 1 | DK31: 1 | DL31: 1 | DM31: 1 | DN31: 1 | DO31: 1 | DP31: 1 | DQ31: 1 | DR31: 1 | DS31: 1 | DT31: 1 | DU31: 1 | DV31: 1 | DW31: 1 | DX31: 1 | DY31: 1 | DZ31: 1 | EA31: 1 | EB31: 1 | EC31: 1 | ED31: 1 | EE31: 1 | EF31: 1 | EG31: 1 | EH31: 1 | EI31: 1 | EJ31: 1 | EK31: 1 | EL31: 1 | EM31: 1 | EN31: 1 | EO31: 1 | EP31: 1 | EQ31: 1 | ER31: 1 | ES31: =SUM(I32:R32) -> 10 | ET31: =SUM(S31:AB31) -> 10 | EU31: =SUM(AC31:AL31) -> 6 | EV31: =SUM(AM31:AV31) -> 10 | EW31: =SUM(BG31:BP31) -> 10 | EX31: =SUM(BG31:BP31) -> 10 | EY31: =SUM(BQ31:BZ31) -> 10 | EZ31: =SUM(CA31:CJ31) -> 0 | FA31: =SUM(CK31:CT31) -> 10 | FB31: =SUM(CU31:DD31) -> 10 | FC31: =SUM(DE31:DN31) -> 10 | FD31: =SUM(DO31:DX31) -> 10 | FE31: =SUM(DY31:EH31) -> 10 | FF31: =SUM(EI31:ER31) -> 10 | FG31: =ROW(FG29) -> 29 | FH31: =SUM(ES31:FF31) -> 126 | FI31: =SUM(I7:ER7)-SUM(ES31:FF31) -> 2 | FJ31: =SUM(FH31:FI31) -> 128
B32: =IF(ISTEXT(D32),1,0) -> 1 | C32: 25 | D32: AGUGBOM PRINCE | G32: 45915 | I32: 1 | J32: 1 | K32: 1 | L32: 1 | M32: 1 | N32: 1 | O32: 1 | P32: 1 | Q32: 1 | R32: 1 | S32: 0 | T32: 0 | U32: 0 | V32: 0 | W32: 0 | X32: 0 | Y32: 0 | Z32: 0 | AA32: 0 | AB32: 0 | AC32: 0 | AD32: 0 | AE32: 0 | AF32: 0 | AI32: 0 | AJ32: 0 | AK32: 1 | AL32: 1 | AM32: 1 | AN32: 1 | AO32: 1 | AP32: 1 | AQ32: 1 | AR32: 1 | AS32: 1 | AT32: 1 | AU32: 1 | AV32: 1 | AW32: 1 | AX32: 1 | AY32: 1 | AZ32: 1 | BA32: 1 | BB32: 1 | BC32: 1 | BD32: 1 | BE32: 0 | BF32: 0 | BG32: 1 | BH32: 1 | BI32: 1 | BJ32: 1 | BK32: 1 | BL32: 1 | BM32: 1 | BN32: 1 | BO32: 1 | BP32: 1 | BQ32: 1 | BR32: 1 | BS32: 0 | BT32: 0 | BU32: 0 | BV32: 0 | BW32: 1 | BX32: 1 | BY32: 0 | BZ32: 0 | CK32: 1 | CL32: 1 | CM32: 1 | CN32: 1 | CO32: 1 | CP32: 1 | CQ32: 1 | CR32: 1 | CS32: 1 | CT32: 1 | CU32: 1 | CV32: 1 | CW32: 1 | CX32: 1 | CY32: 1 | CZ32: 1 | DA32: 1 | DB32: 1 | DC32: 1 | DD32: 1 | DE32: 1 | DF32: 1 | DG32: 1 | DH32: 1 | DI32: 1 | DJ32: 1 | DK32: 1 | DL32: 1 | DM32: 1 | DN32: 1 | DO32: 1 | DP32: 1 | DQ32: 1 | DR32: 1 | DS32: 1 | DT32: 1 | DU32: 1 | DV32: 1 | DW32: 1 | DX32: 1 | DY32: 1 | DZ32: 1 | EA32: 1 | EB32: 1 | EC32: 1 | ED32: 1 | EE32: 1 | EF32: 1 | EG32: 1 | EH32: 1 | EI32: 1 | EJ32: 1 | EK32: 1 | EL32: 1 | EM32: 1 | EN32: 1 | EO32: 1 | EP32: 1 | EQ32: 1 | ER32: 1 | ES32: =SUM(I33:R33) -> 0 | ET32: =SUM(S32:AB32) -> 0 | EU32: =SUM(AC32:AL32) -> 2 | EV32: =SUM(AM32:AV32) -> 10 | EW32: =SUM(BG32:BP32) -> 10 | EX32: =SUM(BG32:BP32) -> 10 | EY32: =SUM(BQ32:BZ32) -> 4 | EZ32: =SUM(CA32:CJ32) -> 0 | FA32: =SUM(CK32:CT32) -> 10 | FB32: =SUM(CU32:DD32) -> 10 | FC32: =SUM(DE32:DN32) -> 10 | FD32: =SUM(DO32:DX32) -> 10 | FE32: =SUM(DY32:EH32) -> 10 | FF32: =SUM(EI32:ER32) -> 10 | FG32: =ROW(FG30) -> 30 | FH32: =SUM(ES32:FF32) -> 96 | FI32: =SUM(I7:ER7)-SUM(ES32:FF32) -> 32 | FJ32: =SUM(FH32:FI32) -> 128
B33: =IF(ISTEXT(D33),1,0) -> 1 | C33: 26 | D33: AYINIDE ADEWALE | G33: 45915 | I33: 0 | J33: 0 | K33: 0 | L33: 0 | M33: 0 | N33: 0 | O33: 0 | P33: 0 | Q33: 0 | R33: 0 | S33: 0 | T33: 0 | U33: 0 | V33: 0 | W33: 0 | X33: 0 | Y33: 0 | Z33: 0 | AA33: 0 | AB33: 0 | AC33: 0 | AD33: 0 | AE33: 0 | AF33: 0 | AI33: 1 | AJ33: 1 | AK33: 1 | AL33: 1 | AM33: 1 | AN33: 1 | AO33: 1 | AP33: 1 | AQ33: 1 | AR33: 1 | AS33: 1 | AT33: 1 | AU33: 0 | AV33: 0 | AW33: 0 | AX33: 0 | AY33: 1 | AZ33: 1 | BA33: 1 | BB33: 1 | BC33: 1 | BD33: 1 | BE33: 1 | BF33: 1 | BG33: 1 | BH33: 1 | BI33: 1 | BJ33: 1 | BK33: 1 | BL33: 1 | BM33: 1 | BN33: 1 | BO33: 1 | BP33: 1 | BQ33: 1 | BR33: 1 | BS33: 1 | BT33: 1 | BU33: 1 | BV33: 1 | BW33: 1 | BX33: 1 | BY33: 1 | BZ33: 1 | CK33: 1 | CL33: 1 | CM33: 1 | CN33: 1 | CO33: 1 | CP33: 1 | CQ33: 1 | CR33: 1 | CS33: 1 | CT33: 1 | CU33: 0 | CV33: 0 | CW33: 0 | CX33: 0 | CY33: 1 | CZ33: 1 | DA33: 0 | DB33: 0 | DC33: 1 | DD33: 1 | DE33: 0 | DF33: 0 | DG33: 0 | DH33: 0 | DI33: 0 | DJ33: 0 | DK33: 1 | DL33: 1 | DM33: 1 | DN33: 1 | DO33: 1 | DP33: 1 | DQ33: 1 | DR33: 1 | DS33: 1 | DT33: 1 | DU33: 1 | DV33: 1 | DW33: 1 | DX33: 1 | DY33: 1 | DZ33: 1 | EA33: 1 | EB33: 1 | EC33: 1 | ED33: 1 | EE33: 1 | EF33: 1 | EG33: 1 | EH33: 1 | EI33: 1 | EJ33: 1 | EK33: 1 | EL33: 1 | EM33: 1 | EN33: 1 | EO33: 1 | EP33: 1 | EQ33: 1 | ER33: 1 | ES33: =SUM(I34:R34) -> 0 | ET33: =SUM(S33:AB33) -> 0 | EU33: =SUM(AC33:AL33) -> 4 | EV33: =SUM(AM33:AV33) -> 8 | EW33: =SUM(BG33:BP33) -> 10 | EX33: =SUM(BG33:BP33) -> 10 | EY33: =SUM(BQ33:BZ33) -> 10 | EZ33: =SUM(CA33:CJ33) -> 0 | FA33: =SUM(CK33:CT33) -> 10 | FB33: =SUM(CU33:DD33) -> 4 | FC33: =SUM(DE33:DN33) -> 4 | FD33: =SUM(DO33:DX33) -> 10 | FE33: =SUM(DY33:EH33) -> 10 | FF33: =SUM(EI33:ER33) -> 10 | FG33: =ROW(FG31) -> 31 | FH33: =SUM(ES33:FF33) -> 90 | FI33: =SUM(I7:ER7)-SUM(ES33:FF33) -> 38 | FJ33: =SUM(FH33:FI33) -> 128
B34: =IF(ISTEXT(D34),1,0) -> 1 | C34: 27 | D34: ELEWURO MUBARAK | G34: 45915 | I34: 0 | J34: 0 | K34: 0 | L34: 0 | M34: 0 | N34: 0 | O34: 0 | P34: 0 | Q34: 0 | R34: 0 | S34: 0 | T34: 0 | U34: 0 | V34: 0 | W34: 0 | X34: 0 | Y34: 0 | Z34: 0 | AA34: 0 | AB34: 0 | AC34: 0 | AD34: 0 | AE34: 0 | AF34: 0 | AI34: 1 | AJ34: 1 | AK34: 1 | AL34: 1 | AM34: 1 | AN34: 1 | AO34: 1 | AP34: 1 | AQ34: 1 | AR34: 1 | AS34: 1 | AT34: 1 | AU34: 1 | AV34: 1 | AW34: 1 | AX34: 1 | AY34: 1 | AZ34: 1 | BA34: 1 | BB34: 1 | BC34: 0 | BD34: 0 | BE34: 1 | BF34: 1 | BG34: 1 | BH34: 1 | BI34: 0 | BJ34: 0 | BK34: 1 | BL34: 1 | BM34: 1 | BN34: 1 | BO34: 0 | BP34: 0 | BQ34: 1 | BR34: 1 | BS34: 1 | BT34: 1 | BU34: 1 | BV34: 1 | BW34: 1 | BX34: 1 | BY34: 1 | BZ34: 1 | CK34: 1 | CL34: 1 | CM34: 1 | CN34: 1 | CO34: 1 | CP34: 1 | CQ34: 1 | CR34: 1 | CS34: 1 | CT34: 1 | CU34: 1 | CV34: 1 | CW34: 1 | CX34: 1 | CY34: 1 | CZ34: 1 | DA34: 1 | DB34: 1 | DC34: 1 | DD34: 1 | DE34: 1 | DF34: 1 | DG34: 1 | DH34: 1 | DI34: 1 | DJ34: 1 | DK34: 1 | DL34: 1 | DM34: 1 | DN34: 1 | DO34: 1 | DP34: 1 | DQ34: 1 | DR34: 1 | DS34: 1 | DT34: 1 | DU34: 1 | DV34: 1 | DW34: 1 | DX34: 1 | DY34: 1 | DZ34: 1 | EA34: 1 | EB34: 1 | EC34: 1 | ED34: 1 | EE34: 1 | EF34: 1 | EG34: 1 | EH34: 1 | EI34: 1 | EJ34: 1 | EK34: 1 | EL34: 1 | EM34: 1 | EN34: 1 | EO34: 1 | EP34: 1 | EQ34: 1 | ER34: 1 | ES34: =SUM(I35:R35) -> 0 | ET34: =SUM(S34:AB34) -> 0 | EU34: =SUM(AC34:AL34) -> 4 | EV34: =SUM(AM34:AV34) -> 10 | EW34: =SUM(BG34:BP34) -> 6 | EX34: =SUM(BG34:BP34) -> 6 | EY34: =SUM(BQ34:BZ34) -> 10 | EZ34: =SUM(CA34:CJ34) -> 0 | FA34: =SUM(CK34:CT34) -> 10 | FB34: =SUM(CU34:DD34) -> 10 | FC34: =SUM(DE34:DN34) -> 10 | FD34: =SUM(DO34:DX34) -> 10 | FE34: =SUM(DY34:EH34) -> 10 | FF34: =SUM(EI34:ER34) -> 10 | FG34: =ROW(FG32) -> 32 | FH34: =SUM(ES34:FF34) -> 96 | FI34: =SUM(I7:ER7)-SUM(ES34:FF34) -> 32 | FJ34: =SUM(FH34:FI34) -> 128
B35: =IF(ISTEXT(D35),1,0) -> 1 | C35: 28 | D35: SUROJUDEEN JUBRIL | G35: 45915 | I35: 0 | J35: 0 | K35: 0 | L35: 0 | M35: 0 | N35: 0 | O35: 0 | P35: 0 | Q35: 0 | R35: 0 | S35: 0 | T35: 0 | U35: 0 | V35: 0 | W35: 0 | X35: 0 | Y35: 0 | Z35: 0 | AA35: 0 | AB35: 0 | AC35: 0 | AD35: 0 | AE35: 0 | AF35: 0 | AI35: 0 | AJ35: 0 | AK35: 1 | AL35: 1 | AM35: 1 | AN35: 1 | AO35: 1 | AP35: 1 | AQ35: 1 | AR35: 1 | AS35: 1 | AT35: 1 | AU35: 1 | AV35: 1 | AW35: 1 | AX35: 1 | AY35: 1 | AZ35: 1 | BA35: 1 | BB35: 1 | BC35: 1 | BD35: 1 | BE35: 1 | BF35: 1 | BG35: 1 | BH35: 1 | BI35: 1 | BJ35: 1 | BK35: 1 | BL35: 1 | BM35: 1 | BN35: 1 | BO35: 1 | BP35: 1 | BQ35: 1 | BR35: 1 | BS35: 1 | BT35: 1 | BU35: 1 | BV35: 1 | BW35: 1 | BX35: 1 | BY35: 1 | BZ35: 1 | CK35: 1 | CL35: 1 | CM35: 1 | CN35: 1 | CO35: 1 | CP35: 1 | CQ35: 1 | CR35: 1 | CS35: 1 | CT35: 1 | CU35: 1 | CV35: 1 | CW35: 1 | CX35: 1 | CY35: 1 | CZ35: 1 | DA35: 1 | DB35: 1 | DC35: 1 | DD35: 1 | DE35: 1 | DF35: 1 | DG35: 1 | DH35: 1 | DI35: 1 | DJ35: 1 | DK35: 1 | DL35: 1 | DM35: 1 | DN35: 1 | DO35: 1 | DP35: 1 | DQ35: 1 | DR35: 1 | DS35: 1 | DT35: 1 | DU35: 1 | DV35: 1 | DW35: 1 | DX35: 1 | DY35: 1 | DZ35: 1 | EA35: 1 | EB35: 1 | EC35: 1 | ED35: 1 | EE35: 1 | EF35: 1 | EG35: 1 | EH35: 1 | EI35: 1 | EJ35: 1 | EK35: 1 | EL35: 1 | EM35: 1 | EN35: 1 | EO35: 1 | EP35: 1 | EQ35: 1 | ER35: 1 | ES35: =SUM(I36:R36) -> 10 | ET35: =SUM(S35:AB35) -> 0 | EU35: =SUM(AC35:AL35) -> 2 | EV35: =SUM(AM35:AV35) -> 10 | EW35: =SUM(BG35:BP35) -> 10 | EX35: =SUM(BG35:BP35) -> 10 | EY35: =SUM(BQ35:BZ35) -> 10 | EZ35: =SUM(CA35:CJ35) -> 0 | FA35: =SUM(CK35:CT35) -> 10 | FB35: =SUM(CU35:DD35) -> 10 | FC35: =SUM(DE35:DN35) -> 10 | FD35: =SUM(DO35:DX35) -> 10 | FE35: =SUM(DY35:EH35) -> 10 | FF35: =SUM(EI35:ER35) -> 10 | FG35: =ROW(FG33) -> 33 | FH35: =SUM(ES35:FF35) -> 112 | FI35: =SUM(I7:ER7)-SUM(ES35:FF35) -> 16 | FJ35: =SUM(FH35:FI35) -> 128
B36: =IF(ISTEXT(D36),1,0) -> 1 | C36: 29 | D36: MUDASHIRU FARUQ | G36: 45915 | I36: 1 | J36: 1 | K36: 1 | L36: 1 | M36: 1 | N36: 1 | O36: 1 | P36: 1 | Q36: 1 | R36: 1 | S36: 0 | T36: 0 | U36: 0 | V36: 0 | W36: 0 | X36: 0 | Y36: 0 | Z36: 0 | AA36: 0 | AB36: 0 | AC36: 0 | AD36: 0 | AE36: 0 | AF36: 0 | AI36: 0 | AJ36: 0 | AK36: 0 | AL36: 0 | AM36: 1 | AN36: 1 | AO36: 1 | AP36: 1 | AQ36: 1 | AR36: 1 | AS36: 1 | AT36: 1 | AU36: 1 | AV36: 1 | AW36: 1 | AX36: 1 | AY36: 1 | AZ36: 1 | BA36: 1 | BB36: 1 | BC36: 1 | BD36: 1 | BE36: 1 | BF36: 1 | BG36: 1 | BH36: 1 | BI36: 1 | BJ36: 1 | BK36: 1 | BL36: 1 | BM36: 1 | BN36: 1 | BO36: 1 | BP36: 1 | BQ36: 1 | BR36: 1 | BS36: 1 | BT36: 1 | BU36: 1 | BV36: 1 | BW36: 1 | BX36: 1 | BY36: 1 | BZ36: 1 | CK36: 1 | CL36: 1 | CM36: 1 | CN36: 1 | CO36: 1 | CP36: 1 | CQ36: 1 | CR36: 1 | CS36: 1 | CT36: 1 | CU36: 1 | CV36: 1 | CW36: 1 | CX36: 1 | CY36: 1 | CZ36: 1 | DA36: 1 | DB36: 1 | DC36: 1 | DD36: 1 | DE36: 1 | DF36: 1 | DG36: 1 | DH36: 1 | DI36: 1 | DJ36: 1 | DK36: 1 | DL36: 1 | DM36: 1 | DN36: 1 | DO36: 1 | DP36: 1 | DQ36: 1 | DR36: 1 | DS36: 1 | DT36: 1 | DU36: 1 | DV36: 1 | DW36: 1 | DX36: 1 | DY36: 1 | DZ36: 1 | EA36: 1 | EB36: 1 | EC36: 1 | ED36: 1 | EE36: 1 | EF36: 1 | EG36: 1 | EH36: 1 | EI36: 1 | EJ36: 1 | EK36: 1 | EL36: 1 | EM36: 1 | EN36: 1 | EO36: 1 | EP36: 1 | EQ36: 1 | ER36: 1 | ES36: =SUM(I37:R37) -> 10 | ET36: =SUM(S36:AB36) -> 0 | EU36: =SUM(AC36:AL36) -> 0 | EV36: =SUM(AM36:AV36) -> 10 | EW36: =SUM(BG36:BP36) -> 10 | EX36: =SUM(BG36:BP36) -> 10 | EY36: =SUM(BQ36:BZ36) -> 10 | EZ36: =SUM(CA36:CJ36) -> 0 | FA36: =SUM(CK36:CT36) -> 10 | FB36: =SUM(CU36:DD36) -> 10 | FC36: =SUM(DE36:DN36) -> 10 | FD36: =SUM(DO36:DX36) -> 10 | FE36: =SUM(DY36:EH36) -> 10 | FF36: =SUM(EI36:ER36) -> 10 | FG36: =ROW(FG34) -> 34 | FH36: =SUM(ES36:FF36) -> 110 | FI36: =SUM(I7:ER7)-SUM(ES36:FF36) -> 18 | FJ36: =SUM(FH36:FI36) -> 128
B37: =IF(ISTEXT(D37),1,0) -> 1 | C37: 30 | D37: SATURDAY GODSTIME | G37: 45915 | I37: 1 | J37: 1 | K37: 1 | L37: 1 | M37: 1 | N37: 1 | O37: 1 | P37: 1 | Q37: 1 | R37: 1 | S37: 0 | T37: 0 | U37: 0 | V37: 0 | W37: 0 | X37: 0 | Y37: 0 | Z37: 0 | AA37: 0 | AB37: 0 | AC37: 0 | AD37: 0 | AE37: 0 | AF37: 0 | AI37: 0 | AJ37: 0 | AK37: 0 | AL37: 0 | AM37: 1 | AN37: 1 | AO37: 0 | AP37: 0 | AQ37: 1 | AR37: 1 | AS37: 1 | AT37: 1 | AU37: 1 | AV37: 1 | AW37: 1 | AX37: 1 | AY37: 1 | AZ37: 1 | BA37: 1 | BB37: 1 | BC37: 1 | BD37: 1 | BE37: 1 | BF37: 1 | BG37: 1 | BH37: 1 | BI37: 1 | BJ37: 1 | BK37: 1 | BL37: 1 | BM37: 1 | BN37: 1 | BO37: 1 | BP37: 1 | BQ37: 1 | BR37: 1 | BS37: 1 | BT37: 1 | BU37: 1 | BV37: 1 | BW37: 1 | BX37: 1 | BY37: 1 | BZ37: 1 | CK37: 1 | CL37: 1 | CM37: 1 | CN37: 1 | CO37: 1 | CP37: 1 | CQ37: 1 | CR37: 1 | CS37: 1 | CT37: 1 | CU37: 1 | CV37: 1 | CW37: 1 | CX37: 1 | CY37: 1 | CZ37: 1 | DA37: 1 | DB37: 1 | DC37: 1 | DD37: 1 | DE37: 1 | DF37: 1 | DG37: 1 | DH37: 1 | DI37: 1 | DJ37: 1 | DK37: 1 | DL37: 1 | DM37: 1 | DN37: 1 | DO37: 1 | DP37: 1 | DQ37: 1 | DR37: 1 | DS37: 1 | DT37: 1 | DU37: 1 | DV37: 1 | DW37: 1 | DX37: 1 | DY37: 1 | DZ37: 1 | EA37: 1 | EB37: 1 | EC37: 1 | ED37: 1 | EE37: 1 | EF37: 1 | EG37: 1 | EH37: 1 | EI37: 1 | EJ37: 1 | EK37: 1 | EL37: 1 | EM37: 1 | EN37: 1 | EO37: 1 | EP37: 1 | EQ37: 1 | ER37: 1 | ES37: =SUM(I38:R38) -> 0 | ET37: =SUM(S37:AB37) -> 0 | EU37: =SUM(AC37:AL37) -> 0 | EV37: =SUM(AM37:AV37) -> 8 | EW37: =SUM(BG37:BP37) -> 10 | EX37: =SUM(BG37:BP37) -> 10 | EY37: =SUM(BQ37:BZ37) -> 10 | EZ37: =SUM(CA37:CJ37) -> 0 | FA37: =SUM(CK37:CT37) -> 10 | FB37: =SUM(CU37:DD37) -> 10 | FC37: =SUM(DE37:DN37) -> 10 | FD37: =SUM(DO37:DX37) -> 10 | FE37: =SUM(DY37:EH37) -> 10 | FF37: =SUM(EI37:ER37) -> 10 | FG37: =ROW(FG35) -> 35 | FH37: =SUM(ES37:FF37) -> 98 | FI37: =SUM(I7:ER7)-SUM(ES37:FF37) -> 30 | FJ37: =SUM(FH37:FI37) -> 128
